<?xml version="1.0" ?>
<robot name="nybble" xmlns:xacro="http://www.ros.org/wiki/xacro">

<xacro:include filename="$(find nybble_description)/urdf/materials.xacro" />
<xacro:include filename="$(find nybble_description)/urdf/nybble.trans" />
<xacro:include filename="$(find nybble_description)/urdf/nybble.gazebo" />
<link name="base_link">
  <inertial>
    <origin xyz="0.0006437778545068246 -1.9796585092736672e-07 0.0867698715532656" rpy="0 0 0"/>
    <mass value="0.06216756972771602"/>
    <inertia ixx="3.8e-05" iyy="0.00015" izz="0.000173" ixy="0.0" iyz="-0.0" ixz="1e-06"/>
  </inertial>
  <visual>
    <origin xyz="0 0 0" rpy="0 0 0"/>
    <geometry>
      <mesh filename="package://nybble_description/meshes/base_link.stl" scale="0.001 0.001 0.001"/>
    </geometry>
    <material name="silver"/>
  </visual>
  <collision>
    <origin xyz="0 0 0" rpy="0 0 0"/>
    <geometry>
      <mesh filename="package://nybble_description/meshes/base_link.stl" scale="0.001 0.001 0.001"/>
    </geometry>
  </collision>
</link>

<link name="servo_rfs__1">
  <inertial>
    <origin xyz="-0.009391892773793674 0.007113387665536201 0.009391793971691972" rpy="0 0 0"/>
    <mass value="0.02098976110153441"/>
    <inertia ixx="2e-06" iyy="1e-06" izz="2e-06" ixy="0.0" iyz="-0.0" ixz="0.0"/>
  </inertial>
  <visual>
    <origin xyz="-0.066161 0.0355 -0.075887" rpy="0 0 0"/>
    <geometry>
      <mesh filename="package://nybble_description/meshes/servo_rfs__1.stl" scale="0.001 0.001 0.001"/>
    </geometry>
    <material name="silver"/>
  </visual>
  <collision>
    <origin xyz="-0.066161 0.0355 -0.075887" rpy="0 0 0"/>
    <geometry>
      <mesh filename="package://nybble_description/meshes/servo_rfs__1.stl" scale="0.001 0.001 0.001"/>
    </geometry>
  </collision>
</link>

<link name="thigh_rf_1">
  <inertial>
    <origin xyz="-0.011499723013290601 0.0004179604201668338 -0.019917178526256143" rpy="0 0 0"/>
    <mass value="0.005724344673721123"/>
    <inertia ixx="2e-06" iyy="2e-06" izz="1e-06" ixy="-0.0" iyz="0.0" ixz="-1e-06"/>
  </inertial>
  <visual>
    <origin xyz="-0.06015 0.05095 -0.081897" rpy="0 0 0"/>
    <geometry>
      <mesh filename="package://nybble_description/meshes/thigh_rf_1.stl" scale="0.001 0.001 0.001"/>
    </geometry>
    <material name="silver"/>
  </visual>
  <collision>
    <origin xyz="-0.06015 0.05095 -0.081897" rpy="0 0 0"/>
    <geometry>
      <mesh filename="package://nybble_description/meshes/thigh_rf_1.stl" scale="0.001 0.001 0.001"/>
    </geometry>
  </collision>
</link>

<link name="horn_2__1">
  <inertial>
    <origin xyz="-2.9481265247301158e-05 0.004404355130528552 -5.0991291569608965e-05" rpy="0 0 0"/>
    <mass value="0.0003743287333075135"/>
    <inertia ixx="0.0" iyy="0.0" izz="0.0" ixy="-0.0" iyz="-0.0" ixz="-0.0"/>
  </inertial>
  <visual>
    <origin xyz="-0.03715 0.05345 -0.04206" rpy="0 0 0"/>
    <geometry>
      <mesh filename="package://nybble_description/meshes/horn_2__1.stl" scale="0.001 0.001 0.001"/>
    </geometry>
    <material name="silver"/>
  </visual>
  <collision>
    <origin xyz="-0.03715 0.05345 -0.04206" rpy="0 0 0"/>
    <geometry>
      <mesh filename="package://nybble_description/meshes/horn_2__1.stl" scale="0.001 0.001 0.001"/>
    </geometry>
  </collision>
</link>

<link name="shank_rf_1">
  <inertial>
    <origin xyz="0.022063118340856336 0.005124999999999692 -0.020635044765108627" rpy="0 0 0"/>
    <mass value="0.003933580408054078"/>
    <inertia ixx="1e-06" iyy="2e-06" izz="1e-06" ixy="0.0" iyz="0.0" ixz="1e-06"/>
  </inertial>
  <visual>
    <origin xyz="-0.03114 0.03745 -0.048071" rpy="0 0 0"/>
    <geometry>
      <mesh filename="package://nybble_description/meshes/shank_rf_1.stl" scale="0.001 0.001 0.001"/>
    </geometry>
    <material name="silver"/>
  </visual>
  <collision>
    <origin xyz="-0.03114 0.03745 -0.048071" rpy="0 0 0"/>
    <geometry>
      <mesh filename="package://nybble_description/meshes/shank_rf_1.stl" scale="0.001 0.001 0.001"/>
    </geometry>
  </collision>
</link>

<link name="servo_lfs__1">
  <inertial>
    <origin xyz="-0.009391892773793674 -0.007113387665536201 0.009391793971691972" rpy="0 0 0"/>
    <mass value="0.02098976110153441"/>
    <inertia ixx="2e-06" iyy="1e-06" izz="2e-06" ixy="-0.0" iyz="0.0" ixz="0.0"/>
  </inertial>
  <visual>
    <origin xyz="-0.066161 -0.0355 -0.075887" rpy="0 0 0"/>
    <geometry>
      <mesh filename="package://nybble_description/meshes/servo_lfs__1.stl" scale="0.001 0.001 0.001"/>
    </geometry>
    <material name="silver"/>
  </visual>
  <collision>
    <origin xyz="-0.066161 -0.0355 -0.075887" rpy="0 0 0"/>
    <geometry>
      <mesh filename="package://nybble_description/meshes/servo_lfs__1.stl" scale="0.001 0.001 0.001"/>
    </geometry>
  </collision>
</link>

<link name="thigh_lf__1">
  <inertial>
    <origin xyz="-0.011500452243449526 -0.00041796046106960805 -0.01991844430049277" rpy="0 0 0"/>
    <mass value="0.005724351981607909"/>
    <inertia ixx="2e-06" iyy="2e-06" izz="1e-06" ixy="0.0" iyz="0.0" ixz="-1e-06"/>
  </inertial>
  <visual>
    <origin xyz="-0.06015 -0.05095 -0.081897" rpy="0 0 0"/>
    <geometry>
      <mesh filename="package://nybble_description/meshes/thigh_lf__1.stl" scale="0.001 0.001 0.001"/>
    </geometry>
    <material name="silver"/>
  </visual>
  <collision>
    <origin xyz="-0.06015 -0.05095 -0.081897" rpy="0 0 0"/>
    <geometry>
      <mesh filename="package://nybble_description/meshes/thigh_lf__1.stl" scale="0.001 0.001 0.001"/>
    </geometry>
  </collision>
</link>

<link name="horn_4_1">
  <inertial>
    <origin xyz="-2.948126530852302e-05 -0.004404355130392661 -5.099129154604448e-05" rpy="0 0 0"/>
    <mass value="0.0003743287331832211"/>
    <inertia ixx="0.0" iyy="0.0" izz="0.0" ixy="0.0" iyz="0.0" ixz="-0.0"/>
  </inertial>
  <visual>
    <origin xyz="-0.03715 -0.05345 -0.04206" rpy="0 0 0"/>
    <geometry>
      <mesh filename="package://nybble_description/meshes/horn_4_1.stl" scale="0.001 0.001 0.001"/>
    </geometry>
    <material name="silver"/>
  </visual>
  <collision>
    <origin xyz="-0.03715 -0.05345 -0.04206" rpy="0 0 0"/>
    <geometry>
      <mesh filename="package://nybble_description/meshes/horn_4_1.stl" scale="0.001 0.001 0.001"/>
    </geometry>
  </collision>
</link>

<link name="shank_lf__1">
  <inertial>
    <origin xyz="0.02206311834085621 -0.005124999999999949 -0.02063504476510683" rpy="0 0 0"/>
    <mass value="0.0039335804080540635"/>
    <inertia ixx="1e-06" iyy="2e-06" izz="1e-06" ixy="0.0" iyz="0.0" ixz="1e-06"/>
  </inertial>
  <visual>
    <origin xyz="-0.03114 -0.03745 -0.048071" rpy="0 0 0"/>
    <geometry>
      <mesh filename="package://nybble_description/meshes/shank_lf__1.stl" scale="0.001 0.001 0.001"/>
    </geometry>
    <material name="silver"/>
  </visual>
  <collision>
    <origin xyz="-0.03114 -0.03745 -0.048071" rpy="0 0 0"/>
    <geometry>
      <mesh filename="package://nybble_description/meshes/shank_lf__1.stl" scale="0.001 0.001 0.001"/>
    </geometry>
  </collision>
</link>

<link name="servo_lrs__1">
  <inertial>
    <origin xyz="0.00939189277379366 -0.007113387665536163 0.009391793971692" rpy="0 0 0"/>
    <mass value="0.020989761101534415"/>
    <inertia ixx="2e-06" iyy="1e-06" izz="2e-06" ixy="0.0" iyz="0.0" ixz="-0.0"/>
  </inertial>
  <visual>
    <origin xyz="0.066161 -0.0355 -0.075887" rpy="0 0 0"/>
    <geometry>
      <mesh filename="package://nybble_description/meshes/servo_lrs__1.stl" scale="0.001 0.001 0.001"/>
    </geometry>
    <material name="silver"/>
  </visual>
  <collision>
    <origin xyz="0.066161 -0.0355 -0.075887" rpy="0 0 0"/>
    <geometry>
      <mesh filename="package://nybble_description/meshes/servo_lrs__1.stl" scale="0.001 0.001 0.001"/>
    </geometry>
  </collision>
</link>

<link name="thigh_rr_1">
  <inertial>
    <origin xyz="0.011501448993691994 0.00041796042016688933 -0.019918435961196267" rpy="0 0 0"/>
    <mass value="0.0057243446737210955"/>
    <inertia ixx="2e-06" iyy="2e-06" izz="1e-06" ixy="0.0" iyz="-0.0" ixz="1e-06"/>
  </inertial>
  <visual>
    <origin xyz="0.060151 0.05095 -0.081897" rpy="0 0 0"/>
    <geometry>
      <mesh filename="package://nybble_description/meshes/thigh_rr_1.stl" scale="0.001 0.001 0.001"/>
    </geometry>
    <material name="silver"/>
  </visual>
  <collision>
    <origin xyz="0.060151 0.05095 -0.081897" rpy="0 0 0"/>
    <geometry>
      <mesh filename="package://nybble_description/meshes/thigh_rr_1.stl" scale="0.001 0.001 0.001"/>
    </geometry>
  </collision>
</link>

<link name="horn_6_1">
  <inertial>
    <origin xyz="3.560028485974365e-05 0.004396463077954972 -5.648517688295468e-05" rpy="0 0 0"/>
    <mass value="0.0003733288579944334"/>
    <inertia ixx="0.0" iyy="0.0" izz="0.0" ixy="0.0" iyz="-0.0" ixz="0.0"/>
  </inertial>
  <visual>
    <origin xyz="0.037151 0.05345 -0.04206" rpy="0 0 0"/>
    <geometry>
      <mesh filename="package://nybble_description/meshes/horn_6_1.stl" scale="0.001 0.001 0.001"/>
    </geometry>
    <material name="silver"/>
  </visual>
  <collision>
    <origin xyz="0.037151 0.05345 -0.04206" rpy="0 0 0"/>
    <geometry>
      <mesh filename="package://nybble_description/meshes/horn_6_1.stl" scale="0.001 0.001 0.001"/>
    </geometry>
  </collision>
</link>

<link name="shank_rr_1">
  <inertial>
    <origin xyz="-0.022063118340855635 0.005125000000000067 -0.020635044765108686" rpy="0 0 0"/>
    <mass value="0.003933580408054078"/>
    <inertia ixx="1e-06" iyy="2e-06" izz="1e-06" ixy="0.0" iyz="0.0" ixz="-1e-06"/>
  </inertial>
  <visual>
    <origin xyz="0.03114 0.03745 -0.048071" rpy="0 0 0"/>
    <geometry>
      <mesh filename="package://nybble_description/meshes/shank_rr_1.stl" scale="0.001 0.001 0.001"/>
    </geometry>
    <material name="silver"/>
  </visual>
  <collision>
    <origin xyz="0.03114 0.03745 -0.048071" rpy="0 0 0"/>
    <geometry>
      <mesh filename="package://nybble_description/meshes/shank_rr_1.stl" scale="0.001 0.001 0.001"/>
    </geometry>
  </collision>
</link>

<link name="servo_rrs__1">
  <inertial>
    <origin xyz="0.009391892773793653 0.007113387665536177 0.009391793971692014" rpy="0 0 0"/>
    <mass value="0.020989761101534412"/>
    <inertia ixx="2e-06" iyy="1e-06" izz="2e-06" ixy="-0.0" iyz="-0.0" ixz="-0.0"/>
  </inertial>
  <visual>
    <origin xyz="0.066161 0.0355 -0.075887" rpy="0 0 0"/>
    <geometry>
      <mesh filename="package://nybble_description/meshes/servo_rrs__1.stl" scale="0.001 0.001 0.001"/>
    </geometry>
    <material name="silver"/>
  </visual>
  <collision>
    <origin xyz="0.066161 0.0355 -0.075887" rpy="0 0 0"/>
    <geometry>
      <mesh filename="package://nybble_description/meshes/servo_rrs__1.stl" scale="0.001 0.001 0.001"/>
    </geometry>
  </collision>
</link>

<link name="thigh_lr__1">
  <inertial>
    <origin xyz="0.011500717243418286 -0.00041796046107026724 -0.019917171243073295" rpy="0 0 0"/>
    <mass value="0.0057243519816078834"/>
    <inertia ixx="2e-06" iyy="2e-06" izz="1e-06" ixy="-0.0" iyz="-0.0" ixz="1e-06"/>
  </inertial>
  <visual>
    <origin xyz="0.060151 -0.05095 -0.081897" rpy="0 0 0"/>
    <geometry>
      <mesh filename="package://nybble_description/meshes/thigh_lr__1.stl" scale="0.001 0.001 0.001"/>
    </geometry>
    <material name="silver"/>
  </visual>
  <collision>
    <origin xyz="0.060151 -0.05095 -0.081897" rpy="0 0 0"/>
    <geometry>
      <mesh filename="package://nybble_description/meshes/thigh_lr__1.stl" scale="0.001 0.001 0.001"/>
    </geometry>
  </collision>
</link>

<link name="shank_lr_1">
  <inertial>
    <origin xyz="-0.02206311834085492 -0.005124999999999755 -0.020635044765107732" rpy="0 0 0"/>
    <mass value="0.003933580408054066"/>
    <inertia ixx="1e-06" iyy="2e-06" izz="1e-06" ixy="0.0" iyz="0.0" ixz="-1e-06"/>
  </inertial>
  <visual>
    <origin xyz="0.03114 -0.03745 -0.048071" rpy="0 0 0"/>
    <geometry>
      <mesh filename="package://nybble_description/meshes/shank_lr_1.stl" scale="0.001 0.001 0.001"/>
    </geometry>
    <material name="silver"/>
  </visual>
  <collision>
    <origin xyz="0.03114 -0.03745 -0.048071" rpy="0 0 0"/>
    <geometry>
      <mesh filename="package://nybble_description/meshes/shank_lr_1.stl" scale="0.001 0.001 0.001"/>
    </geometry>
  </collision>
</link>

<link name="horn_7__1">
  <inertial>
    <origin xyz="3.560028493236611e-05 -0.004396463077816076 -5.648517687767418e-05" rpy="0 0 0"/>
    <mass value="0.0003733288578701408"/>
    <inertia ixx="0.0" iyy="0.0" izz="0.0" ixy="-0.0" iyz="0.0" ixz="0.0"/>
  </inertial>
  <visual>
    <origin xyz="0.037151 -0.05345 -0.04206" rpy="0 0 0"/>
    <geometry>
      <mesh filename="package://nybble_description/meshes/horn_7__1.stl" scale="0.001 0.001 0.001"/>
    </geometry>
    <material name="silver"/>
  </visual>
  <collision>
    <origin xyz="0.037151 -0.05345 -0.04206" rpy="0 0 0"/>
    <geometry>
      <mesh filename="package://nybble_description/meshes/horn_7__1.stl" scale="0.001 0.001 0.001"/>
    </geometry>
  </collision>
</link>

<link name="servo_tail__1">
  <inertial>
    <origin xyz="0.01656893664391256 -9.001271957916746e-12 0.0036800206065446955" rpy="0 0 0"/>
    <mass value="0.020989761101534474"/>
    <inertia ixx="2e-06" iyy="2e-06" izz="1e-06" ixy="-0.0" iyz="0.0" ixz="0.0"/>
  </inertial>
  <visual>
    <origin xyz="0.070403 0.0 -0.08013" rpy="0 0 0"/>
    <geometry>
      <mesh filename="package://nybble_description/meshes/servo_tail__1.stl" scale="0.001 0.001 0.001"/>
    </geometry>
    <material name="silver"/>
  </visual>
  <collision>
    <origin xyz="0.070403 0.0 -0.08013" rpy="0 0 0"/>
    <geometry>
      <mesh filename="package://nybble_description/meshes/servo_tail__1.stl" scale="0.001 0.001 0.001"/>
    </geometry>
  </collision>
</link>

<link name="servo_neck__1">
  <inertial>
    <origin xyz="-0.009797854141403106 -0.006000000009001055 -0.009463830116931984" rpy="0 0 0"/>
    <mass value="0.020989761101534467"/>
    <inertia ixx="2e-06" iyy="2e-06" izz="1e-06" ixy="0.0" iyz="0.0" ixz="-0.0"/>
  </inertial>
  <visual>
    <origin xyz="-0.06305 -0.006 -0.092292" rpy="0 0 0"/>
    <geometry>
      <mesh filename="package://nybble_description/meshes/servo_neck__1.stl" scale="0.001 0.001 0.001"/>
    </geometry>
    <material name="silver"/>
  </visual>
  <collision>
    <origin xyz="-0.06305 -0.006 -0.092292" rpy="0 0 0"/>
    <geometry>
      <mesh filename="package://nybble_description/meshes/servo_neck__1.stl" scale="0.001 0.001 0.001"/>
    </geometry>
  </collision>
</link>

<link name="ultrasonic__1">
  <inertial>
    <origin xyz="0.003910980396568162 7.906731711417384e-10 -0.01078696269194207" rpy="0 0 0"/>
    <mass value="0.009405277809877379"/>
    <inertia ixx="2e-06" iyy="1e-06" izz="2e-06" ixy="0.0" iyz="0.0" ixz="-0.0"/>
  </inertial>
  <visual>
    <origin xyz="-0.098041 -0.0006 -0.129239" rpy="0 0 0"/>
    <geometry>
      <mesh filename="package://nybble_description/meshes/ultrasonic__1.stl" scale="0.001 0.001 0.001"/>
    </geometry>
    <material name="silver"/>
  </visual>
  <collision>
    <origin xyz="-0.098041 -0.0006 -0.129239" rpy="0 0 0"/>
    <geometry>
      <mesh filename="package://nybble_description/meshes/ultrasonic__1.stl" scale="0.001 0.001 0.001"/>
    </geometry>
  </collision>
</link>

<link name="head__1">
  <inertial>
    <origin xyz="0.013363478067596177 0.003199983666020581 -0.013638252988965177" rpy="0 0 0"/>
    <mass value="0.014832489000511479"/>
    <inertia ixx="5e-06" iyy="4e-06" izz="4e-06" ixy="-0.0" iyz="-0.0" ixz="0.0"/>
  </inertial>
  <visual>
    <origin xyz="-0.086526 0.0026 -0.129592" rpy="0 0 0"/>
    <geometry>
      <mesh filename="package://nybble_description/meshes/head__1.stl" scale="0.001 0.001 0.001"/>
    </geometry>
    <material name="silver"/>
  </visual>
  <collision>
    <origin xyz="-0.086526 0.0026 -0.129592" rpy="0 0 0"/>
    <geometry>
      <mesh filename="package://nybble_description/meshes/head__1.stl" scale="0.001 0.001 0.001"/>
    </geometry>
  </collision>
</link>

<link name="horn_10_1">
  <inertial>
    <origin xyz="0.0037758126633431893 0.0015309102143479143 0.004844510403711533" rpy="0 0 0"/>
    <mass value="0.0018987062282855255"/>
    <inertia ixx="0.0" iyy="0.0" izz="0.0" ixy="-0.0" iyz="0.0" ixz="0.0"/>
  </inertial>
  <visual>
    <origin xyz="-0.080511 0.0161 -0.106002" rpy="0 0 0"/>
    <geometry>
      <mesh filename="package://nybble_description/meshes/horn_10_1.stl" scale="0.001 0.001 0.001"/>
    </geometry>
    <material name="silver"/>
  </visual>
  <collision>
    <origin xyz="-0.080511 0.0161 -0.106002" rpy="0 0 0"/>
    <geometry>
      <mesh filename="package://nybble_description/meshes/horn_10_1.stl" scale="0.001 0.001 0.001"/>
    </geometry>
  </collision>
</link>

<link name="neck__1">
  <inertial>
    <origin xyz="-0.0022623829814073654 -8.940220774040458e-11 0.010429961100509741" rpy="0 0 0"/>
    <mass value="0.005864126689763961"/>
    <inertia ixx="2e-06" iyy="0.0" izz="2e-06" ixy="-0.0" iyz="-0.0" ixz="0.0"/>
  </inertial>
  <visual>
    <origin xyz="-0.071003 0.0 -0.096162" rpy="0 0 0"/>
    <geometry>
      <mesh filename="package://nybble_description/meshes/neck__1.stl" scale="0.001 0.001 0.001"/>
    </geometry>
    <material name="silver"/>
  </visual>
  <collision>
    <origin xyz="-0.071003 0.0 -0.096162" rpy="0 0 0"/>
    <geometry>
      <mesh filename="package://nybble_description/meshes/neck__1.stl" scale="0.001 0.001 0.001"/>
    </geometry>
  </collision>
</link>

<link name="tail_1">
  <inertial>
    <origin xyz="-0.03997762353339566 -8.923383321951712e-11 -0.0449435890214674" rpy="0 0 0"/>
    <mass value="0.008386608374857928"/>
    <inertia ixx="4e-06" iyy="8e-06" izz="5e-06" ixy="0.0" iyz="0.0" ixz="-4e-06"/>
  </inertial>
  <visual>
    <origin xyz="0.060008 0.0 -0.108909" rpy="0 0 0"/>
    <geometry>
      <mesh filename="package://nybble_description/meshes/tail_1.stl" scale="0.001 0.001 0.001"/>
    </geometry>
    <material name="silver"/>
  </visual>
  <collision>
    <origin xyz="0.060008 0.0 -0.108909" rpy="0 0 0"/>
    <geometry>
      <mesh filename="package://nybble_description/meshes/tail_1.stl" scale="0.001 0.001 0.001"/>
    </geometry>
  </collision>
</link>

<link name="screwr_1_1">
  <inertial>
    <origin xyz="0.0016671343231915159 -5.923314920248755e-07 -0.001634457332853112" rpy="0 0 0"/>
    <mass value="0.00021522443277177425"/>
    <inertia ixx="-0.0" iyy="-0.0" izz="0.0" ixy="0.0" iyz="-0.0" ixz="-0.0"/>
  </inertial>
  <visual>
    <origin xyz="0.060008 0.0 -0.108909" rpy="0 0 0"/>
    <geometry>
      <mesh filename="package://nybble_description/meshes/screwr_1_1.stl" scale="0.001 0.001 0.001"/>
    </geometry>
    <material name="silver"/>
  </visual>
  <collision>
    <origin xyz="0.060008 0.0 -0.108909" rpy="0 0 0"/>
    <geometry>
      <mesh filename="package://nybble_description/meshes/screwr_1_1.stl" scale="0.001 0.001 0.001"/>
    </geometry>
  </collision>
</link>

<link name="pcb__1">
  <inertial>
    <origin xyz="0.028604463024900117 0.02526528795593727 -0.001931837248098811" rpy="0 0 0"/>
    <mass value="0.010242691597873327"/>
    <inertia ixx="2e-06" iyy="4e-06" izz="6e-06" ixy="-0.0" iyz="-0.0" ixz="0.0"/>
  </inertial>
  <visual>
    <origin xyz="0.029 0.0245 -0.094478" rpy="0 0 0"/>
    <geometry>
      <mesh filename="package://nybble_description/meshes/pcb__1.stl" scale="0.001 0.001 0.001"/>
    </geometry>
    <material name="silver"/>
  </visual>
  <collision>
    <origin xyz="0.029 0.0245 -0.094478" rpy="0 0 0"/>
    <geometry>
      <mesh filename="package://nybble_description/meshes/pcb__1.stl" scale="0.001 0.001 0.001"/>
    </geometry>
  </collision>
</link>

<link name="battery_1">
  <inertial>
    <origin xyz="0.005960245134894697 0.00023367888629849154 -0.005944469658890172" rpy="0 0 0"/>
    <mass value="0.006686722506179021"/>
    <inertia ixx="1e-06" iyy="3e-06" izz="4e-06" ixy="0.0" iyz="0.0" ixz="-0.0"/>
  </inertial>
  <visual>
    <origin xyz="0.00924 0.0 -0.073412" rpy="0 0 0"/>
    <geometry>
      <mesh filename="package://nybble_description/meshes/battery_1.stl" scale="0.001 0.001 0.001"/>
    </geometry>
    <material name="silver"/>
  </visual>
  <collision>
    <origin xyz="0.00924 0.0 -0.073412" rpy="0 0 0"/>
    <geometry>
      <mesh filename="package://nybble_description/meshes/battery_1.stl" scale="0.001 0.001 0.001"/>
    </geometry>
  </collision>
</link>

<link name="screwr_4_1">
  <inertial>
    <origin xyz="-4.271861519244968e-05 0.0023861698130614034 4.689859276349462e-05" rpy="0 0 0"/>
    <mass value="0.00021522443277175132"/>
    <inertia ixx="0.0" iyy="-0.0" izz="0.0" ixy="0.0" iyz="-0.0" ixz="-0.0"/>
  </inertial>
  <visual>
    <origin xyz="0.066161 0.0375 -0.075887" rpy="0 0 0"/>
    <geometry>
      <mesh filename="package://nybble_description/meshes/screwr_4_1.stl" scale="0.001 0.001 0.001"/>
    </geometry>
    <material name="silver"/>
  </visual>
  <collision>
    <origin xyz="0.066161 0.0375 -0.075887" rpy="0 0 0"/>
    <geometry>
      <mesh filename="package://nybble_description/meshes/screwr_4_1.stl" scale="0.001 0.001 0.001"/>
    </geometry>
  </collision>
</link>

<link name="screwr_5_1">
  <inertial>
    <origin xyz="-2.944811618878912e-05 0.0023862323839166505 5.8389771658506895e-05" rpy="0 0 0"/>
    <mass value="0.00021522443277171256"/>
    <inertia ixx="0.0" iyy="-0.0" izz="0.0" ixy="0.0" iyz="-0.0" ixz="-0.0"/>
  </inertial>
  <visual>
    <origin xyz="0.046645 0.0375 -0.095403" rpy="0 0 0"/>
    <geometry>
      <mesh filename="package://nybble_description/meshes/screwr_5_1.stl" scale="0.001 0.001 0.001"/>
    </geometry>
    <material name="silver"/>
  </visual>
  <collision>
    <origin xyz="0.046645 0.0375 -0.095403" rpy="0 0 0"/>
    <geometry>
      <mesh filename="package://nybble_description/meshes/screwr_5_1.stl" scale="0.001 0.001 0.001"/>
    </geometry>
  </collision>
</link>

<link name="screwr_2_1">
  <inertial>
    <origin xyz="-3.251304112146525e-05 0.0023861698130601405 1.895200141854847e-05" rpy="0 0 0"/>
    <mass value="0.00021522443277171134"/>
    <inertia ixx="0.0" iyy="-0.0" izz="0.0" ixy="0.0" iyz="-0.0" ixz="-0.0"/>
  </inertial>
  <visual>
    <origin xyz="0.050656 0.0375 -0.028555" rpy="0 0 0"/>
    <geometry>
      <mesh filename="package://nybble_description/meshes/screwr_2_1.stl" scale="0.001 0.001 0.001"/>
    </geometry>
    <material name="silver"/>
  </visual>
  <collision>
    <origin xyz="0.050656 0.0375 -0.028555" rpy="0 0 0"/>
    <geometry>
      <mesh filename="package://nybble_description/meshes/screwr_2_1.stl" scale="0.001 0.001 0.001"/>
    </geometry>
  </collision>
</link>

<link name="screwr_3_1">
  <inertial>
    <origin xyz="-2.015446011273056e-05 0.002386169813060196 3.1310582427106215e-05" rpy="0 0 0"/>
    <mass value="0.00021522443277171237"/>
    <inertia ixx="0.0" iyy="-0.0" izz="0.0" ixy="0.0" iyz="-0.0" ixz="-0.0"/>
  </inertial>
  <visual>
    <origin xyz="0.03114 0.0375 -0.048071" rpy="0 0 0"/>
    <geometry>
      <mesh filename="package://nybble_description/meshes/screwr_3_1.stl" scale="0.001 0.001 0.001"/>
    </geometry>
    <material name="silver"/>
  </visual>
  <collision>
    <origin xyz="0.03114 0.0375 -0.048071" rpy="0 0 0"/>
    <geometry>
      <mesh filename="package://nybble_description/meshes/screwr_3_1.stl" scale="0.001 0.001 0.001"/>
    </geometry>
  </collision>
</link>

<link name="screwr_6_1">
  <inertial>
    <origin xyz="3.034334174138731e-05 0.0023861698130597936 1.678178758966753e-05" rpy="0 0 0"/>
    <mass value="0.0002152244327717165"/>
    <inertia ixx="0.0" iyy="-0.0" izz="0.0" ixy="-0.0" iyz="-0.0" ixz="0.0"/>
  </inertial>
  <visual>
    <origin xyz="-0.050656 0.0375 -0.028555" rpy="0 0 0"/>
    <geometry>
      <mesh filename="package://nybble_description/meshes/screwr_6_1.stl" scale="0.001 0.001 0.001"/>
    </geometry>
    <material name="silver"/>
  </visual>
  <collision>
    <origin xyz="-0.050656 0.0375 -0.028555" rpy="0 0 0"/>
    <geometry>
      <mesh filename="package://nybble_description/meshes/screwr_6_1.stl" scale="0.001 0.001 0.001"/>
    </geometry>
  </collision>
</link>

<link name="screwr_7_1">
  <inertial>
    <origin xyz="1.79847607320871e-05 0.00238616981306055 2.914036859776037e-05" rpy="0 0 0"/>
    <mass value="0.0002152244327717336"/>
    <inertia ixx="0.0" iyy="-0.0" izz="0.0" ixy="-0.0" iyz="-0.0" ixz="0.0"/>
  </inertial>
  <visual>
    <origin xyz="-0.03114 0.0375 -0.048071" rpy="0 0 0"/>
    <geometry>
      <mesh filename="package://nybble_description/meshes/screwr_7_1.stl" scale="0.001 0.001 0.001"/>
    </geometry>
    <material name="silver"/>
  </visual>
  <collision>
    <origin xyz="-0.03114 0.0375 -0.048071" rpy="0 0 0"/>
    <geometry>
      <mesh filename="package://nybble_description/meshes/screwr_7_1.stl" scale="0.001 0.001 0.001"/>
    </geometry>
  </collision>
</link>

<link name="screw_9_1">
  <inertial>
    <origin xyz="4.188320501498366e-05 0.002386169813059502 4.606266813729498e-05" rpy="0 0 0"/>
    <mass value="0.00021522443277170806"/>
    <inertia ixx="0.0" iyy="-0.0" izz="0.0" ixy="-0.0" iyz="-0.0" ixz="0.0"/>
  </inertial>
  <visual>
    <origin xyz="-0.066161 0.0375 -0.075887" rpy="0 0 0"/>
    <geometry>
      <mesh filename="package://nybble_description/meshes/screw_9_1.stl" scale="0.001 0.001 0.001"/>
    </geometry>
    <material name="silver"/>
  </visual>
  <collision>
    <origin xyz="-0.066161 0.0375 -0.075887" rpy="0 0 0"/>
    <geometry>
      <mesh filename="package://nybble_description/meshes/screw_9_1.stl" scale="0.001 0.001 0.001"/>
    </geometry>
  </collision>
</link>

<link name="screw_8_1">
  <inertial>
    <origin xyz="2.8266454689902798e-05 0.002386169813060862 5.838977166003345e-05" rpy="0 0 0"/>
    <mass value="0.00021522443277171332"/>
    <inertia ixx="0.0" iyy="-0.0" izz="0.0" ixy="-0.0" iyz="-0.0" ixz="0.0"/>
  </inertial>
  <visual>
    <origin xyz="-0.046645 0.0375 -0.095403" rpy="0 0 0"/>
    <geometry>
      <mesh filename="package://nybble_description/meshes/screw_8_1.stl" scale="0.001 0.001 0.001"/>
    </geometry>
    <material name="silver"/>
  </visual>
  <collision>
    <origin xyz="-0.046645 0.0375 -0.095403" rpy="0 0 0"/>
    <geometry>
      <mesh filename="package://nybble_description/meshes/screw_8_1.stl" scale="0.001 0.001 0.001"/>
    </geometry>
  </collision>
</link>

<link name="screwr_14_1">
  <inertial>
    <origin xyz="4.1883205027556936e-05 -0.002386169807744136 4.606266799724035e-05" rpy="0 0 0"/>
    <mass value="0.00021522443128645102"/>
    <inertia ixx="0.0" iyy="-0.0" izz="0.0" ixy="0.0" iyz="0.0" ixz="0.0"/>
  </inertial>
  <visual>
    <origin xyz="-0.066161 -0.0375 -0.075887" rpy="0 0 0"/>
    <geometry>
      <mesh filename="package://nybble_description/meshes/screwr_14_1.stl" scale="0.001 0.001 0.001"/>
    </geometry>
    <material name="silver"/>
  </visual>
  <collision>
    <origin xyz="-0.066161 -0.0375 -0.075887" rpy="0 0 0"/>
    <geometry>
      <mesh filename="package://nybble_description/meshes/screwr_14_1.stl" scale="0.001 0.001 0.001"/>
    </geometry>
  </collision>
</link>

<link name="screwr_20_1">
  <inertial>
    <origin xyz="2.8266454367480154e-05 -0.002386169807745399 5.838977193438344e-05" rpy="0 0 0"/>
    <mass value="0.0002152244312864444"/>
    <inertia ixx="0.0" iyy="-0.0" izz="0.0" ixy="0.0" iyz="0.0" ixz="0.0"/>
  </inertial>
  <visual>
    <origin xyz="-0.046645 -0.0375 -0.095403" rpy="0 0 0"/>
    <geometry>
      <mesh filename="package://nybble_description/meshes/screwr_20_1.stl" scale="0.001 0.001 0.001"/>
    </geometry>
    <material name="silver"/>
  </visual>
  <collision>
    <origin xyz="-0.046645 -0.0375 -0.095403" rpy="0 0 0"/>
    <geometry>
      <mesh filename="package://nybble_description/meshes/screwr_20_1.stl" scale="0.001 0.001 0.001"/>
    </geometry>
  </collision>
</link>

<link name="screwr_16_1">
  <inertial>
    <origin xyz="1.798488683956226e-05 -0.0023861698077451907 2.9140495519205944e-05" rpy="0 0 0"/>
    <mass value="0.00021522443128646005"/>
    <inertia ixx="0.0" iyy="-0.0" izz="0.0" ixy="0.0" iyz="0.0" ixz="0.0"/>
  </inertial>
  <visual>
    <origin xyz="-0.03114 -0.0375 -0.048071" rpy="0 0 0"/>
    <geometry>
      <mesh filename="package://nybble_description/meshes/screwr_16_1.stl" scale="0.001 0.001 0.001"/>
    </geometry>
    <material name="silver"/>
  </visual>
  <collision>
    <origin xyz="-0.03114 -0.0375 -0.048071" rpy="0 0 0"/>
    <geometry>
      <mesh filename="package://nybble_description/meshes/screwr_16_1.stl" scale="0.001 0.001 0.001"/>
    </geometry>
  </collision>
</link>

<link name="screwr_15_1">
  <inertial>
    <origin xyz="3.0343467933111046e-05 -0.002386169807744483 1.6781914426843708e-05" rpy="0 0 0"/>
    <mass value="0.00021522443128645135"/>
    <inertia ixx="0.0" iyy="-0.0" izz="0.0" ixy="0.0" iyz="0.0" ixz="0.0"/>
  </inertial>
  <visual>
    <origin xyz="-0.050656 -0.0375 -0.028555" rpy="0 0 0"/>
    <geometry>
      <mesh filename="package://nybble_description/meshes/screwr_15_1.stl" scale="0.001 0.001 0.001"/>
    </geometry>
    <material name="silver"/>
  </visual>
  <collision>
    <origin xyz="-0.050656 -0.0375 -0.028555" rpy="0 0 0"/>
    <geometry>
      <mesh filename="package://nybble_description/meshes/screwr_15_1.stl" scale="0.001 0.001 0.001"/>
    </geometry>
  </collision>
</link>

<link name="screwr_18_1">
  <inertial>
    <origin xyz="-2.944811691403537e-05 -0.002386232378601659 5.838977193281525e-05" rpy="0 0 0"/>
    <mass value="0.00021522443128644397"/>
    <inertia ixx="0.0" iyy="-0.0" izz="0.0" ixy="-0.0" iyz="0.0" ixz="-0.0"/>
  </inertial>
  <visual>
    <origin xyz="0.046645 -0.0375 -0.095403" rpy="0 0 0"/>
    <geometry>
      <mesh filename="package://nybble_description/meshes/screwr_18_1.stl" scale="0.001 0.001 0.001"/>
    </geometry>
    <material name="silver"/>
  </visual>
  <collision>
    <origin xyz="0.046645 -0.0375 -0.095403" rpy="0 0 0"/>
    <geometry>
      <mesh filename="package://nybble_description/meshes/screwr_18_1.stl" scale="0.001 0.001 0.001"/>
    </geometry>
  </collision>
</link>

<link name="screwr_19_1">
  <inertial>
    <origin xyz="-4.2718615945860905e-05 -0.002386169807745829 4.689859336429181e-05" rpy="0 0 0"/>
    <mass value="0.00021522443128646704"/>
    <inertia ixx="0.0" iyy="-0.0" izz="0.0" ixy="-0.0" iyz="0.0" ixz="-0.0"/>
  </inertial>
  <visual>
    <origin xyz="0.066161 -0.0375 -0.075887" rpy="0 0 0"/>
    <geometry>
      <mesh filename="package://nybble_description/meshes/screwr_19_1.stl" scale="0.001 0.001 0.001"/>
    </geometry>
    <material name="silver"/>
  </visual>
  <collision>
    <origin xyz="0.066161 -0.0375 -0.075887" rpy="0 0 0"/>
    <geometry>
      <mesh filename="package://nybble_description/meshes/screwr_19_1.stl" scale="0.001 0.001 0.001"/>
    </geometry>
  </collision>
</link>

<link name="screwr_21_1">
  <inertial>
    <origin xyz="-3.251304106705738e-05 -0.0023861698077447327 1.895200200955141e-05" rpy="0 0 0"/>
    <mass value="0.0002152244312864459"/>
    <inertia ixx="0.0" iyy="-0.0" izz="0.0" ixy="-0.0" iyz="0.0" ixz="-0.0"/>
  </inertial>
  <visual>
    <origin xyz="0.050656 -0.0375 -0.028555" rpy="0 0 0"/>
    <geometry>
      <mesh filename="package://nybble_description/meshes/screwr_21_1.stl" scale="0.001 0.001 0.001"/>
    </geometry>
    <material name="silver"/>
  </visual>
  <collision>
    <origin xyz="0.050656 -0.0375 -0.028555" rpy="0 0 0"/>
    <geometry>
      <mesh filename="package://nybble_description/meshes/screwr_21_1.stl" scale="0.001 0.001 0.001"/>
    </geometry>
  </collision>
</link>

<link name="screwr_17_1">
  <inertial>
    <origin xyz="-2.015445997408105e-05 -0.002386169807744788 3.131058310240631e-05" rpy="0 0 0"/>
    <mass value="0.00021522443128644964"/>
    <inertia ixx="0.0" iyy="-0.0" izz="0.0" ixy="-0.0" iyz="0.0" ixz="-0.0"/>
  </inertial>
  <visual>
    <origin xyz="0.03114 -0.0375 -0.048071" rpy="0 0 0"/>
    <geometry>
      <mesh filename="package://nybble_description/meshes/screwr_17_1.stl" scale="0.001 0.001 0.001"/>
    </geometry>
    <material name="silver"/>
  </visual>
  <collision>
    <origin xyz="0.03114 -0.0375 -0.048071" rpy="0 0 0"/>
    <geometry>
      <mesh filename="package://nybble_description/meshes/screwr_17_1.stl" scale="0.001 0.001 0.001"/>
    </geometry>
  </collision>
</link>

<link name="screwr_11_1">
  <inertial>
    <origin xyz="5.125395315012937e-05 0.002407412529187479 8.273053920221374e-05" rpy="0 0 0"/>
    <mass value="0.00021522443277170064"/>
    <inertia ixx="-0.0" iyy="-0.0" izz="0.0" ixy="-0.0" iyz="-0.0" ixz="0.0"/>
  </inertial>
  <visual>
    <origin xyz="-0.086527 0.0031 -0.129592" rpy="0 0 0"/>
    <geometry>
      <mesh filename="package://nybble_description/meshes/screwr_11_1.stl" scale="0.001 0.001 0.001"/>
    </geometry>
    <material name="silver"/>
  </visual>
  <collision>
    <origin xyz="-0.086527 0.0031 -0.129592" rpy="0 0 0"/>
    <geometry>
      <mesh filename="package://nybble_description/meshes/screwr_11_1.stl" scale="0.001 0.001 0.001"/>
    </geometry>
  </collision>
</link>

<link name="screwr_10_1">
  <inertial>
    <origin xyz="5.17815608435529e-05 0.0024074125291874255 6.528582382671344e-05" rpy="0 0 0"/>
    <mass value="0.0002152244327717019"/>
    <inertia ixx="0.0" iyy="-0.0" izz="0.0" ixy="-0.0" iyz="-0.0" ixz="0.0"/>
  </inertial>
  <visual>
    <origin xyz="-0.085082 0.0031 -0.10203" rpy="0 0 0"/>
    <geometry>
      <mesh filename="package://nybble_description/meshes/screwr_10_1.stl" scale="0.001 0.001 0.001"/>
    </geometry>
    <material name="silver"/>
  </visual>
  <collision>
    <origin xyz="-0.085082 0.0031 -0.10203" rpy="0 0 0"/>
    <geometry>
      <mesh filename="package://nybble_description/meshes/screwr_10_1.stl" scale="0.001 0.001 0.001"/>
    </geometry>
  </collision>
</link>

<link name="screwb_4_1">
  <inertial>
    <origin xyz="-1.2603174959754937e-05 -0.001562517332365669 1.6404144139010868e-05" rpy="0 0 0"/>
    <mass value="0.0001801263252201023"/>
    <inertia ixx="0.0" iyy="-0.0" izz="0.0" ixy="0.0" iyz="-0.0" ixz="-0.0"/>
  </inertial>
  <visual>
    <origin xyz="0.04365 0.0475 -0.053319" rpy="0 0 0"/>
    <geometry>
      <mesh filename="package://nybble_description/meshes/screwb_4_1.stl" scale="0.001 0.001 0.001"/>
    </geometry>
    <material name="silver"/>
  </visual>
  <collision>
    <origin xyz="0.04365 0.0475 -0.053319" rpy="0 0 0"/>
    <geometry>
      <mesh filename="package://nybble_description/meshes/screwb_4_1.stl" scale="0.001 0.001 0.001"/>
    </geometry>
  </collision>
</link>

<link name="screwb_5_1">
  <inertial>
    <origin xyz="-1.0839619729759165e-05 -0.0015625173323657801 1.161510803679433e-05" rpy="0 0 0"/>
    <mass value="0.00018012632522010645"/>
    <inertia ixx="0.0" iyy="0.0" izz="0.0" ixy="0.0" iyz="-0.0" ixz="-0.0"/>
  </inertial>
  <visual>
    <origin xyz="0.040438 0.0475 -0.034267" rpy="0 0 0"/>
    <geometry>
      <mesh filename="package://nybble_description/meshes/screwb_5_1.stl" scale="0.001 0.001 0.001"/>
    </geometry>
    <material name="silver"/>
  </visual>
  <collision>
    <origin xyz="0.040438 0.0475 -0.034267" rpy="0 0 0"/>
    <geometry>
      <mesh filename="package://nybble_description/meshes/screwb_5_1.stl" scale="0.001 0.001 0.001"/>
    </geometry>
  </collision>
</link>

<link name="screwb_6_1">
  <inertial>
    <origin xyz="-7.821532749772986e-06 -0.00156251733236569 1.2808745502003449e-05" rpy="0 0 0"/>
    <mass value="0.00018012632522008563"/>
    <inertia ixx="0.0" iyy="0.0" izz="0.0" ixy="0.0" iyz="-0.0" ixz="-0.0"/>
  </inertial>
  <visual>
    <origin xyz="0.028758 0.0475 -0.041011" rpy="0 0 0"/>
    <geometry>
      <mesh filename="package://nybble_description/meshes/screwb_6_1.stl" scale="0.001 0.001 0.001"/>
    </geometry>
    <material name="silver"/>
  </visual>
  <collision>
    <origin xyz="0.028758 0.0475 -0.041011" rpy="0 0 0"/>
    <geometry>
      <mesh filename="package://nybble_description/meshes/screwb_6_1.stl" scale="0.001 0.001 0.001"/>
    </geometry>
  </collision>
</link>

<link name="screwb_3_1">
  <inertial>
    <origin xyz="1.0905609533068406e-05 -0.0015385313529235126 -1.3204126767224489e-05" rpy="0 0 0"/>
    <mass value="0.00018013856677388468"/>
    <inertia ixx="0.0" iyy="0.0" izz="0.0" ixy="-0.0" iyz="0.0" ixz="0.0"/>
  </inertial>
  <visual>
    <origin xyz="0.05365 0.0475 -0.070639" rpy="0 0 0"/>
    <geometry>
      <mesh filename="package://nybble_description/meshes/screwb_3_1.stl" scale="0.001 0.001 0.001"/>
    </geometry>
    <material name="silver"/>
  </visual>
  <collision>
    <origin xyz="0.05365 0.0475 -0.070639" rpy="0 0 0"/>
    <geometry>
      <mesh filename="package://nybble_description/meshes/screwb_3_1.stl" scale="0.001 0.001 0.001"/>
    </geometry>
  </collision>
</link>

<link name="screwb_2_1">
  <inertial>
    <origin xyz="1.165725450643501e-05 -0.0015385313529227562 -1.639983709192383e-05" rpy="0 0 0"/>
    <mass value="0.00018013856677386378"/>
    <inertia ixx="0.0" iyy="0.0" izz="0.0" ixy="-0.0" iyz="0.0" ixz="0.0"/>
  </inertial>
  <visual>
    <origin xyz="0.056863 0.0475 -0.08969" rpy="0 0 0"/>
    <geometry>
      <mesh filename="package://nybble_description/meshes/screwb_2_1.stl" scale="0.001 0.001 0.001"/>
    </geometry>
    <material name="silver"/>
  </visual>
  <collision>
    <origin xyz="0.056863 0.0475 -0.08969" rpy="0 0 0"/>
    <geometry>
      <mesh filename="package://nybble_description/meshes/screwb_2_1.stl" scale="0.001 0.001 0.001"/>
    </geometry>
  </collision>
</link>

<link name="screwb_1_1">
  <inertial>
    <origin xyz="1.4147385872936846e-05 -0.0015385313529232211 -1.5413303210823348e-05" rpy="0 0 0"/>
    <mass value="0.00018013856677390314"/>
    <inertia ixx="0.0" iyy="0.0" izz="0.0" ixy="-0.0" iyz="0.0" ixz="0.0"/>
  </inertial>
  <visual>
    <origin xyz="0.068543 0.0475 -0.082947" rpy="0 0 0"/>
    <geometry>
      <mesh filename="package://nybble_description/meshes/screwb_1_1.stl" scale="0.001 0.001 0.001"/>
    </geometry>
    <material name="silver"/>
  </visual>
  <collision>
    <origin xyz="0.068543 0.0475 -0.082947" rpy="0 0 0"/>
    <geometry>
      <mesh filename="package://nybble_description/meshes/screwb_1_1.stl" scale="0.001 0.001 0.001"/>
    </geometry>
  </collision>
</link>

<link name="screwb_10_1">
  <inertial>
    <origin xyz="1.2608485129017577e-05 -0.0015622349696174584 1.6343130250548454e-05" rpy="0 0 0"/>
    <mass value="0.00018011234668273565"/>
    <inertia ixx="0.0" iyy="-0.0" izz="0.0" ixy="-0.0" iyz="-0.0" ixz="0.0"/>
  </inertial>
  <visual>
    <origin xyz="-0.04365 0.0475 -0.053319" rpy="0 0 0"/>
    <geometry>
      <mesh filename="package://nybble_description/meshes/screwb_10_1.stl" scale="0.001 0.001 0.001"/>
    </geometry>
    <material name="silver"/>
  </visual>
  <collision>
    <origin xyz="-0.04365 0.0475 -0.053319" rpy="0 0 0"/>
    <geometry>
      <mesh filename="package://nybble_description/meshes/screwb_10_1.stl" scale="0.001 0.001 0.001"/>
    </geometry>
  </collision>
</link>

<link name="screwb_7_1">
  <inertial>
    <origin xyz="-1.1638727855714515e-05 -0.0015386438162938373 -1.6420746909398543e-05" rpy="0 0 0"/>
    <mass value="0.00018015265771514444"/>
    <inertia ixx="0.0" iyy="0.0" izz="0.0" ixy="0.0" iyz="0.0" ixz="-0.0"/>
  </inertial>
  <visual>
    <origin xyz="-0.056863 0.0475 -0.08969" rpy="0 0 0"/>
    <geometry>
      <mesh filename="package://nybble_description/meshes/screwb_7_1.stl" scale="0.001 0.001 0.001"/>
    </geometry>
    <material name="silver"/>
  </visual>
  <collision>
    <origin xyz="-0.056863 0.0475 -0.08969" rpy="0 0 0"/>
    <geometry>
      <mesh filename="package://nybble_description/meshes/screwb_7_1.stl" scale="0.001 0.001 0.001"/>
    </geometry>
  </collision>
</link>

<link name="screwb_12_1">
  <inertial>
    <origin xyz="1.0844858379231714e-05 -0.001562234969617618 1.1553670056049792e-05" rpy="0 0 0"/>
    <mass value="0.00018011234668274933"/>
    <inertia ixx="0.0" iyy="0.0" izz="0.0" ixy="-0.0" iyz="-0.0" ixz="0.0"/>
  </inertial>
  <visual>
    <origin xyz="-0.040438 0.0475 -0.034267" rpy="0 0 0"/>
    <geometry>
      <mesh filename="package://nybble_description/meshes/screwb_12_1.stl" scale="0.001 0.001 0.001"/>
    </geometry>
    <material name="silver"/>
  </visual>
  <collision>
    <origin xyz="-0.040438 0.0475 -0.034267" rpy="0 0 0"/>
    <geometry>
      <mesh filename="package://nybble_description/meshes/screwb_12_1.stl" scale="0.001 0.001 0.001"/>
    </geometry>
  </collision>
</link>

<link name="screwb_11_1">
  <inertial>
    <origin xyz="7.826511404220027e-06 -0.00156223496961784 1.2747457629865011e-05" rpy="0 0 0"/>
    <mass value="0.0001801123466827498"/>
    <inertia ixx="0.0" iyy="0.0" izz="0.0" ixy="-0.0" iyz="-0.0" ixz="0.0"/>
  </inertial>
  <visual>
    <origin xyz="-0.028758 0.0475 -0.041011" rpy="0 0 0"/>
    <geometry>
      <mesh filename="package://nybble_description/meshes/screwb_11_1.stl" scale="0.001 0.001 0.001"/>
    </geometry>
    <material name="silver"/>
  </visual>
  <collision>
    <origin xyz="-0.028758 0.0475 -0.041011" rpy="0 0 0"/>
    <geometry>
      <mesh filename="package://nybble_description/meshes/screwb_11_1.stl" scale="0.001 0.001 0.001"/>
    </geometry>
  </collision>
</link>

<link name="screwb_8_1">
  <inertial>
    <origin xyz="-1.4128690414574874e-05 -0.0015386438162940039 -1.5434310488629532e-05" rpy="0 0 0"/>
    <mass value="0.00018015265771508624"/>
    <inertia ixx="0.0" iyy="0.0" izz="0.0" ixy="0.0" iyz="0.0" ixz="-0.0"/>
  </inertial>
  <visual>
    <origin xyz="-0.068543 0.0475 -0.082947" rpy="0 0 0"/>
    <geometry>
      <mesh filename="package://nybble_description/meshes/screwb_8_1.stl" scale="0.001 0.001 0.001"/>
    </geometry>
    <material name="silver"/>
  </visual>
  <collision>
    <origin xyz="-0.068543 0.0475 -0.082947" rpy="0 0 0"/>
    <geometry>
      <mesh filename="package://nybble_description/meshes/screwb_8_1.stl" scale="0.001 0.001 0.001"/>
    </geometry>
  </collision>
</link>

<link name="screwb_9_1">
  <inertial>
    <origin xyz="-1.0887129317675714e-05 -0.0015386438162948227 -1.3225311934816908e-05" rpy="0 0 0"/>
    <mass value="0.00018015265771518146"/>
    <inertia ixx="0.0" iyy="0.0" izz="0.0" ixy="0.0" iyz="0.0" ixz="-0.0"/>
  </inertial>
  <visual>
    <origin xyz="-0.05365 0.0475 -0.070639" rpy="0 0 0"/>
    <geometry>
      <mesh filename="package://nybble_description/meshes/screwb_9_1.stl" scale="0.001 0.001 0.001"/>
    </geometry>
    <material name="silver"/>
  </visual>
  <collision>
    <origin xyz="-0.05365 0.0475 -0.070639" rpy="0 0 0"/>
    <geometry>
      <mesh filename="package://nybble_description/meshes/screwb_9_1.stl" scale="0.001 0.001 0.001"/>
    </geometry>
  </collision>
</link>

<link name="screw_bat_1">
  <inertial>
    <origin xyz="1.1654140793394135e-05 8.700480990397833e-07 -0.006575340484074543" rpy="0 0 0"/>
    <mass value="0.0002725102019066178"/>
    <inertia ixx="0.0" iyy="0.0" izz="0.0" ixy="-0.0" iyz="0.0" ixz="0.0"/>
  </inertial>
  <visual>
    <origin xyz="0.00924 0.0 -0.084812" rpy="0 0 0"/>
    <geometry>
      <mesh filename="package://nybble_description/meshes/screw_bat_1.stl" scale="0.001 0.001 0.001"/>
    </geometry>
    <material name="silver"/>
  </visual>
  <collision>
    <origin xyz="0.00924 0.0 -0.084812" rpy="0 0 0"/>
    <geometry>
      <mesh filename="package://nybble_description/meshes/screw_bat_1.stl" scale="0.001 0.001 0.001"/>
    </geometry>
  </collision>
</link>

<link name="screw_batt_1">
  <inertial>
    <origin xyz="-1.2578777949131398e-05 8.700480990222878e-07 -0.0065753404840750845" rpy="0 0 0"/>
    <mass value="0.00027251020190662044"/>
    <inertia ixx="0.0" iyy="0.0" izz="0.0" ixy="-0.0" iyz="0.0" ixz="-0.0"/>
  </inertial>
  <visual>
    <origin xyz="-0.01386 0.0 -0.084812" rpy="0 0 0"/>
    <geometry>
      <mesh filename="package://nybble_description/meshes/screw_batt_1.stl" scale="0.001 0.001 0.001"/>
    </geometry>
    <material name="silver"/>
  </visual>
  <collision>
    <origin xyz="-0.01386 0.0 -0.084812" rpy="0 0 0"/>
    <geometry>
      <mesh filename="package://nybble_description/meshes/screw_batt_1.stl" scale="0.001 0.001 0.001"/>
    </geometry>
  </collision>
</link>

<link name="screwb_18_1">
  <inertial>
    <origin xyz="1.0844858282788028e-05 0.0015622349711838096 1.1553670245099956e-05" rpy="0 0 0"/>
    <mass value="0.00018011234798784453"/>
    <inertia ixx="0.0" iyy="0.0" izz="0.0" ixy="0.0" iyz="0.0" ixz="0.0"/>
  </inertial>
  <visual>
    <origin xyz="-0.040438 -0.0475 -0.034267" rpy="0 0 0"/>
    <geometry>
      <mesh filename="package://nybble_description/meshes/screwb_18_1.stl" scale="0.001 0.001 0.001"/>
    </geometry>
    <material name="silver"/>
  </visual>
  <collision>
    <origin xyz="-0.040438 -0.0475 -0.034267" rpy="0 0 0"/>
    <geometry>
      <mesh filename="package://nybble_description/meshes/screwb_18_1.stl" scale="0.001 0.001 0.001"/>
    </geometry>
  </collision>
</link>

<link name="screwb_15_1">
  <inertial>
    <origin xyz="-1.088712899393468e-05 0.001538643814171195 -1.3225312078868345e-05" rpy="0 0 0"/>
    <mass value="0.00018015265642216746"/>
    <inertia ixx="0.0" iyy="0.0" izz="0.0" ixy="-0.0" iyz="-0.0" ixz="-0.0"/>
  </inertial>
  <visual>
    <origin xyz="-0.05365 -0.0475 -0.070639" rpy="0 0 0"/>
    <geometry>
      <mesh filename="package://nybble_description/meshes/screwb_15_1.stl" scale="0.001 0.001 0.001"/>
    </geometry>
    <material name="silver"/>
  </visual>
  <collision>
    <origin xyz="-0.05365 -0.0475 -0.070639" rpy="0 0 0"/>
    <geometry>
      <mesh filename="package://nybble_description/meshes/screwb_15_1.stl" scale="0.001 0.001 0.001"/>
    </geometry>
  </collision>
</link>

<link name="screwb_14_1">
  <inertial>
    <origin xyz="-1.163872753624784e-05 0.0015386438141702374 -1.642074707879082e-05" rpy="0 0 0"/>
    <mass value="0.0001801526564221304"/>
    <inertia ixx="0.0" iyy="0.0" izz="0.0" ixy="-0.0" iyz="-0.0" ixz="-0.0"/>
  </inertial>
  <visual>
    <origin xyz="-0.056863 -0.0475 -0.08969" rpy="0 0 0"/>
    <geometry>
      <mesh filename="package://nybble_description/meshes/screwb_14_1.stl" scale="0.001 0.001 0.001"/>
    </geometry>
    <material name="silver"/>
  </visual>
  <collision>
    <origin xyz="-0.056863 -0.0475 -0.08969" rpy="0 0 0"/>
    <geometry>
      <mesh filename="package://nybble_description/meshes/screwb_14_1.stl" scale="0.001 0.001 0.001"/>
    </geometry>
  </collision>
</link>

<link name="screwb_16_1">
  <inertial>
    <origin xyz="1.2608485025870919e-05 0.0015622349711835945 1.6343130399970596e-05" rpy="0 0 0"/>
    <mass value="0.0001801123479878306"/>
    <inertia ixx="0.0" iyy="-0.0" izz="0.0" ixy="0.0" iyz="0.0" ixz="0.0"/>
  </inertial>
  <visual>
    <origin xyz="-0.04365 -0.0475 -0.053319" rpy="0 0 0"/>
    <geometry>
      <mesh filename="package://nybble_description/meshes/screwb_16_1.stl" scale="0.001 0.001 0.001"/>
    </geometry>
    <material name="silver"/>
  </visual>
  <collision>
    <origin xyz="-0.04365 -0.0475 -0.053319" rpy="0 0 0"/>
    <geometry>
      <mesh filename="package://nybble_description/meshes/screwb_16_1.stl" scale="0.001 0.001 0.001"/>
    </geometry>
  </collision>
</link>

<link name="screwb_13_1">
  <inertial>
    <origin xyz="-1.412869011059581e-05 0.001538643814170397 -1.5434310649084515e-05" rpy="0 0 0"/>
    <mass value="0.0001801526564220723"/>
    <inertia ixx="0.0" iyy="0.0" izz="0.0" ixy="-0.0" iyz="-0.0" ixz="-0.0"/>
  </inertial>
  <visual>
    <origin xyz="-0.068543 -0.0475 -0.082947" rpy="0 0 0"/>
    <geometry>
      <mesh filename="package://nybble_description/meshes/screwb_13_1.stl" scale="0.001 0.001 0.001"/>
    </geometry>
    <material name="silver"/>
  </visual>
  <collision>
    <origin xyz="-0.068543 -0.0475 -0.082947" rpy="0 0 0"/>
    <geometry>
      <mesh filename="package://nybble_description/meshes/screwb_13_1.stl" scale="0.001 0.001 0.001"/>
    </geometry>
  </collision>
</link>

<link name="screwb_17_1">
  <inertial>
    <origin xyz="7.826511332048591e-06 0.001562234971183997 1.2747457804926365e-05" rpy="0 0 0"/>
    <mass value="0.00018011234798784477"/>
    <inertia ixx="0.0" iyy="0.0" izz="0.0" ixy="0.0" iyz="0.0" ixz="0.0"/>
  </inertial>
  <visual>
    <origin xyz="-0.028758 -0.0475 -0.041011" rpy="0 0 0"/>
    <geometry>
      <mesh filename="package://nybble_description/meshes/screwb_17_1.stl" scale="0.001 0.001 0.001"/>
    </geometry>
    <material name="silver"/>
  </visual>
  <collision>
    <origin xyz="-0.028758 -0.0475 -0.041011" rpy="0 0 0"/>
    <geometry>
      <mesh filename="package://nybble_description/meshes/screwb_17_1.stl" scale="0.001 0.001 0.001"/>
    </geometry>
  </collision>
</link>

<link name="screwb_22_1">
  <inertial>
    <origin xyz="-1.2603301720072457e-05 0.0015625173304133697 1.6404270373283902e-05" rpy="0 0 0"/>
    <mass value="0.00018012632392712407"/>
    <inertia ixx="0.0" iyy="-0.0" izz="0.0" ixy="-0.0" iyz="0.0" ixz="-0.0"/>
  </inertial>
  <visual>
    <origin xyz="0.04365 -0.0475 -0.053319" rpy="0 0 0"/>
    <geometry>
      <mesh filename="package://nybble_description/meshes/screwb_22_1.stl" scale="0.001 0.001 0.001"/>
    </geometry>
    <material name="silver"/>
  </visual>
  <collision>
    <origin xyz="0.04365 -0.0475 -0.053319" rpy="0 0 0"/>
    <geometry>
      <mesh filename="package://nybble_description/meshes/screwb_22_1.stl" scale="0.001 0.001 0.001"/>
    </geometry>
  </collision>
</link>

<link name="screwb_23_1">
  <inertial>
    <origin xyz="1.0905483266959726e-05 0.0015385313547148297 -1.3204000355745982e-05" rpy="0 0 0"/>
    <mass value="0.00018013856808051976"/>
    <inertia ixx="0.0" iyy="0.0" izz="0.0" ixy="0.0" iyz="-0.0" ixz="0.0"/>
  </inertial>
  <visual>
    <origin xyz="0.05365 -0.0475 -0.070639" rpy="0 0 0"/>
    <geometry>
      <mesh filename="package://nybble_description/meshes/screwb_23_1.stl" scale="0.001 0.001 0.001"/>
    </geometry>
    <material name="silver"/>
  </visual>
  <collision>
    <origin xyz="0.05365 -0.0475 -0.070639" rpy="0 0 0"/>
    <geometry>
      <mesh filename="package://nybble_description/meshes/screwb_23_1.stl" scale="0.001 0.001 0.001"/>
    </geometry>
  </collision>
</link>

<link name="screwb_24_1">
  <inertial>
    <origin xyz="1.4147259586760885e-05 0.0015385313547146076 -1.5413176782899662e-05" rpy="0 0 0"/>
    <mass value="0.00018013856808053798"/>
    <inertia ixx="0.0" iyy="0.0" izz="0.0" ixy="0.0" iyz="-0.0" ixz="0.0"/>
  </inertial>
  <visual>
    <origin xyz="0.068543 -0.0475 -0.082947" rpy="0 0 0"/>
    <geometry>
      <mesh filename="package://nybble_description/meshes/screwb_24_1.stl" scale="0.001 0.001 0.001"/>
    </geometry>
    <material name="silver"/>
  </visual>
  <collision>
    <origin xyz="0.068543 -0.0475 -0.082947" rpy="0 0 0"/>
    <geometry>
      <mesh filename="package://nybble_description/meshes/screwb_24_1.stl" scale="0.001 0.001 0.001"/>
    </geometry>
  </collision>
</link>

<link name="screwb_19_1">
  <inertial>
    <origin xyz="1.1657128235836867e-05 0.0015385313547140247 -1.6399710654854682e-05" rpy="0 0 0"/>
    <mass value="0.00018013856808049862"/>
    <inertia ixx="0.0" iyy="0.0" izz="0.0" ixy="0.0" iyz="-0.0" ixz="0.0"/>
  </inertial>
  <visual>
    <origin xyz="0.056863 -0.0475 -0.08969" rpy="0 0 0"/>
    <geometry>
      <mesh filename="package://nybble_description/meshes/screwb_19_1.stl" scale="0.001 0.001 0.001"/>
    </geometry>
    <material name="silver"/>
  </visual>
  <collision>
    <origin xyz="0.056863 -0.0475 -0.08969" rpy="0 0 0"/>
    <geometry>
      <mesh filename="package://nybble_description/meshes/screwb_19_1.stl" scale="0.001 0.001 0.001"/>
    </geometry>
  </collision>
</link>

<link name="screwb_20_1">
  <inertial>
    <origin xyz="-1.0839746483380652e-05 0.0015625173304135848 1.1615234231883431e-05" rpy="0 0 0"/>
    <mass value="0.00018012632392712787"/>
    <inertia ixx="0.0" iyy="0.0" izz="0.0" ixy="-0.0" iyz="0.0" ixz="-0.0"/>
  </inertial>
  <visual>
    <origin xyz="0.040438 -0.0475 -0.034267" rpy="0 0 0"/>
    <geometry>
      <mesh filename="package://nybble_description/meshes/screwb_20_1.stl" scale="0.001 0.001 0.001"/>
    </geometry>
    <material name="silver"/>
  </visual>
  <collision>
    <origin xyz="0.040438 -0.0475 -0.034267" rpy="0 0 0"/>
    <geometry>
      <mesh filename="package://nybble_description/meshes/screwb_20_1.stl" scale="0.001 0.001 0.001"/>
    </geometry>
  </collision>
</link>

<link name="screwb_21_1">
  <inertial>
    <origin xyz="-7.821659479340798e-06 0.0015625173304133558 1.280887171095646e-05" rpy="0 0 0"/>
    <mass value="0.00018012632392710748"/>
    <inertia ixx="0.0" iyy="0.0" izz="0.0" ixy="-0.0" iyz="0.0" ixz="-0.0"/>
  </inertial>
  <visual>
    <origin xyz="0.028758 -0.0475 -0.041011" rpy="0 0 0"/>
    <geometry>
      <mesh filename="package://nybble_description/meshes/screwb_21_1.stl" scale="0.001 0.001 0.001"/>
    </geometry>
    <material name="silver"/>
  </visual>
  <collision>
    <origin xyz="0.028758 -0.0475 -0.041011" rpy="0 0 0"/>
    <geometry>
      <mesh filename="package://nybble_description/meshes/screwb_21_1.stl" scale="0.001 0.001 0.001"/>
    </geometry>
  </collision>
</link>

<link name="screw_head_2">
  <inertial>
    <origin xyz="-2.707864305558083e-05 -0.0019184040892117268 -3.406724687335383e-05" rpy="0 0 0"/>
    <mass value="0.00012773741469663697"/>
    <inertia ixx="0.0" iyy="0.0" izz="0.0" ixy="0.0" iyz="0.0" ixz="-0.0"/>
  </inertial>
  <visual>
    <origin xyz="-0.080511 0.0142 -0.106002" rpy="0 0 0"/>
    <geometry>
      <mesh filename="package://nybble_description/meshes/screw_head_2.stl" scale="0.001 0.001 0.001"/>
    </geometry>
    <material name="silver"/>
  </visual>
  <collision>
    <origin xyz="-0.080511 0.0142 -0.106002" rpy="0 0 0"/>
    <geometry>
      <mesh filename="package://nybble_description/meshes/screw_head_2.stl" scale="0.001 0.001 0.001"/>
    </geometry>
  </collision>
</link>

<link name="screw_headd__1">
  <inertial>
    <origin xyz="-2.693919455984406e-05 -0.001918404089211772 -3.405084044214024e-05" rpy="0 0 0"/>
    <mass value="0.00012773741469663697"/>
    <inertia ixx="0.0" iyy="0.0" izz="0.0" ixy="0.0" iyz="0.0" ixz="-0.0"/>
  </inertial>
  <visual>
    <origin xyz="-0.080977 0.0142 -0.115572" rpy="0 0 0"/>
    <geometry>
      <mesh filename="package://nybble_description/meshes/screw_headd__1.stl" scale="0.001 0.001 0.001"/>
    </geometry>
    <material name="silver"/>
  </visual>
  <collision>
    <origin xyz="-0.080977 0.0142 -0.115572" rpy="0 0 0"/>
    <geometry>
      <mesh filename="package://nybble_description/meshes/screw_headd__1.stl" scale="0.001 0.001 0.001"/>
    </geometry>
  </collision>
</link>

<link name="screw_neckk_1">
  <inertial>
    <origin xyz="-0.0014510165787470497 1.0925714298316846e-06 -0.0013196189492413468" rpy="0 0 0"/>
    <mass value="0.00012773741470190105"/>
    <inertia ixx="0.0" iyy="0.0" izz="0.0" ixy="0.0" iyz="0.0" ixz="-0.0"/>
  </inertial>
  <visual>
    <origin xyz="-0.069013 0.0068 -0.103454" rpy="0 0 0"/>
    <geometry>
      <mesh filename="package://nybble_description/meshes/screw_neckk_1.stl" scale="0.001 0.001 0.001"/>
    </geometry>
    <material name="silver"/>
  </visual>
  <collision>
    <origin xyz="-0.069013 0.0068 -0.103454" rpy="0 0 0"/>
    <geometry>
      <mesh filename="package://nybble_description/meshes/screw_neckk_1.stl" scale="0.001 0.001 0.001"/>
    </geometry>
  </collision>
</link>

<link name="screw_neck_1">
  <inertial>
    <origin xyz="-0.00145101657872318 -3.138810972642958e-06 -0.0013196189492099414" rpy="0 0 0"/>
    <mass value="0.00012773741469663372"/>
    <inertia ixx="0.0" iyy="0.0" izz="0.0" ixy="-0.0" iyz="-0.0" ixz="-0.0"/>
  </inertial>
  <visual>
    <origin xyz="-0.069013 -0.0068 -0.103454" rpy="0 0 0"/>
    <geometry>
      <mesh filename="package://nybble_description/meshes/screw_neck_1.stl" scale="0.001 0.001 0.001"/>
    </geometry>
    <material name="silver"/>
  </visual>
  <collision>
    <origin xyz="-0.069013 -0.0068 -0.103454" rpy="0 0 0"/>
    <geometry>
      <mesh filename="package://nybble_description/meshes/screw_neck_1.stl" scale="0.001 0.001 0.001"/>
    </geometry>
  </collision>
</link>

<link name="screwr_12_1">
  <inertial>
    <origin xyz="-0.0017826009133373039 -5.923314929604058e-07 0.0017262695100664985" rpy="0 0 0"/>
    <mass value="0.0002152244327717077"/>
    <inertia ixx="0.0" iyy="-0.0" izz="-0.0" ixy="-0.0" iyz="0.0" ixz="0.0"/>
  </inertial>
  <visual>
    <origin xyz="0.123011 0.0 -0.037279" rpy="0 0 0"/>
    <geometry>
      <mesh filename="package://nybble_description/meshes/screwr_12_1.stl" scale="0.001 0.001 0.001"/>
    </geometry>
    <material name="silver"/>
  </visual>
  <collision>
    <origin xyz="0.123011 0.0 -0.037279" rpy="0 0 0"/>
    <geometry>
      <mesh filename="package://nybble_description/meshes/screwr_12_1.stl" scale="0.001 0.001 0.001"/>
    </geometry>
  </collision>
</link>

<link name="horn_1__1">
  <inertial>
    <origin xyz="3.264471312561246e-05 0.0004464630779546369 6.015514034826697e-05" rpy="0 0 0"/>
    <mass value="0.0003733288579944062"/>
    <inertia ixx="0.0" iyy="0.0" izz="0.0" ixy="0.0" iyz="0.0" ixz="-0.0"/>
  </inertial>
  <visual>
    <origin xyz="-0.06015 0.0495 -0.081897" rpy="0 0 0"/>
    <geometry>
      <mesh filename="package://nybble_description/meshes/horn_1__1.stl" scale="0.001 0.001 0.001"/>
    </geometry>
    <material name="silver"/>
  </visual>
  <collision>
    <origin xyz="-0.06015 0.0495 -0.081897" rpy="0 0 0"/>
    <geometry>
      <mesh filename="package://nybble_description/meshes/horn_1__1.stl" scale="0.001 0.001 0.001"/>
    </geometry>
  </collision>
</link>

<link name="servo_rft_1">
  <inertial>
    <origin xyz="0.0033274175172005663 0.01570537812881538 -0.003326684895286057" rpy="0 0 0"/>
    <mass value="0.0182804731015344"/>
    <inertia ixx="2e-06" iyy="1e-06" izz="2e-06" ixy="-0.0" iyz="0.0" ixz="0.0"/>
  </inertial>
  <visual>
    <origin xyz="-0.03715 0.04595 -0.04206" rpy="0 0 0"/>
    <geometry>
      <mesh filename="package://nybble_description/meshes/servo_rft_1.stl" scale="0.001 0.001 0.001"/>
    </geometry>
    <material name="silver"/>
  </visual>
  <collision>
    <origin xyz="-0.03715 0.04595 -0.04206" rpy="0 0 0"/>
    <geometry>
      <mesh filename="package://nybble_description/meshes/servo_rft_1.stl" scale="0.001 0.001 0.001"/>
    </geometry>
  </collision>
</link>

<link name="horn_5_1">
  <inertial>
    <origin xyz="-3.044489290705138e-05 0.00045435513052870247 5.297244303278936e-05" rpy="0 0 0"/>
    <mass value="0.0003743287333075335"/>
    <inertia ixx="0.0" iyy="0.0" izz="0.0" ixy="-0.0" iyz="0.0" ixz="0.0"/>
  </inertial>
  <visual>
    <origin xyz="0.06015 0.0495 -0.081897" rpy="0 0 0"/>
    <geometry>
      <mesh filename="package://nybble_description/meshes/horn_5_1.stl" scale="0.001 0.001 0.001"/>
    </geometry>
    <material name="silver"/>
  </visual>
  <collision>
    <origin xyz="0.06015 0.0495 -0.081897" rpy="0 0 0"/>
    <geometry>
      <mesh filename="package://nybble_description/meshes/horn_5_1.stl" scale="0.001 0.001 0.001"/>
    </geometry>
  </collision>
</link>

<link name="servo_rrt_1">
  <inertial>
    <origin xyz="-0.0033264175172009677 0.015705378128815735 -0.0033266848952859737" rpy="0 0 0"/>
    <mass value="0.018280473101534418"/>
    <inertia ixx="2e-06" iyy="1e-06" izz="2e-06" ixy="0.0" iyz="0.0" ixz="-0.0"/>
  </inertial>
  <visual>
    <origin xyz="0.037151 0.04595 -0.04206" rpy="0 0 0"/>
    <geometry>
      <mesh filename="package://nybble_description/meshes/servo_rrt_1.stl" scale="0.001 0.001 0.001"/>
    </geometry>
    <material name="silver"/>
  </visual>
  <collision>
    <origin xyz="0.037151 0.04595 -0.04206" rpy="0 0 0"/>
    <geometry>
      <mesh filename="package://nybble_description/meshes/servo_rrt_1.stl" scale="0.001 0.001 0.001"/>
    </geometry>
  </collision>
</link>

<link name="horn_3_1">
  <inertial>
    <origin xyz="3.2644713084915844e-05 -0.00044646307781575495 6.015514040884351e-05" rpy="0 0 0"/>
    <mass value="0.0003733288578701136"/>
    <inertia ixx="0.0" iyy="0.0" izz="0.0" ixy="-0.0" iyz="-0.0" ixz="-0.0"/>
  </inertial>
  <visual>
    <origin xyz="-0.06015 -0.0495 -0.081897" rpy="0 0 0"/>
    <geometry>
      <mesh filename="package://nybble_description/meshes/horn_3_1.stl" scale="0.001 0.001 0.001"/>
    </geometry>
    <material name="silver"/>
  </visual>
  <collision>
    <origin xyz="-0.06015 -0.0495 -0.081897" rpy="0 0 0"/>
    <geometry>
      <mesh filename="package://nybble_description/meshes/horn_3_1.stl" scale="0.001 0.001 0.001"/>
    </geometry>
  </collision>
</link>

<link name="horn_8_1">
  <inertial>
    <origin xyz="-3.044489285623092e-05 -0.00045435513039281117 5.297244307433946e-05" rpy="0 0 0"/>
    <mass value="0.0003743287331832411"/>
    <inertia ixx="0.0" iyy="0.0" izz="0.0" ixy="0.0" iyz="-0.0" ixz="0.0"/>
  </inertial>
  <visual>
    <origin xyz="0.06015 -0.0495 -0.081897" rpy="0 0 0"/>
    <geometry>
      <mesh filename="package://nybble_description/meshes/horn_8_1.stl" scale="0.001 0.001 0.001"/>
    </geometry>
    <material name="silver"/>
  </visual>
  <collision>
    <origin xyz="0.06015 -0.0495 -0.081897" rpy="0 0 0"/>
    <geometry>
      <mesh filename="package://nybble_description/meshes/horn_8_1.stl" scale="0.001 0.001 0.001"/>
    </geometry>
  </collision>
</link>

<link name="servo_lrt__1">
  <inertial>
    <origin xyz="-0.0033264175172009677 -0.01570537812881573 -0.0033266848952859737" rpy="0 0 0"/>
    <mass value="0.018280473101534418"/>
    <inertia ixx="2e-06" iyy="1e-06" izz="2e-06" ixy="-0.0" iyz="-0.0" ixz="-0.0"/>
  </inertial>
  <visual>
    <origin xyz="0.037151 -0.04595 -0.04206" rpy="0 0 0"/>
    <geometry>
      <mesh filename="package://nybble_description/meshes/servo_lrt__1.stl" scale="0.001 0.001 0.001"/>
    </geometry>
    <material name="silver"/>
  </visual>
  <collision>
    <origin xyz="0.037151 -0.04595 -0.04206" rpy="0 0 0"/>
    <geometry>
      <mesh filename="package://nybble_description/meshes/servo_lrt__1.stl" scale="0.001 0.001 0.001"/>
    </geometry>
  </collision>
</link>

<link name="servo_head__1">
  <inertial>
    <origin xyz="0.00024624707037752824 0.015755378039408692 0.004698221906389341" rpy="0 0 0"/>
    <mass value="0.018280473101534887"/>
    <inertia ixx="2e-06" iyy="1e-06" izz="1e-06" ixy="-0.0" iyz="-0.0" ixz="-0.0"/>
  </inertial>
  <visual>
    <origin xyz="-0.085527 0.0116 -0.110519" rpy="0 0 0"/>
    <geometry>
      <mesh filename="package://nybble_description/meshes/servo_head__1.stl" scale="0.001 0.001 0.001"/>
    </geometry>
    <material name="silver"/>
  </visual>
  <collision>
    <origin xyz="-0.085527 0.0116 -0.110519" rpy="0 0 0"/>
    <geometry>
      <mesh filename="package://nybble_description/meshes/servo_head__1.stl" scale="0.001 0.001 0.001"/>
    </geometry>
  </collision>
</link>

<link name="neck_horn_1">
  <inertial>
    <origin xyz="-0.00022396818171910304 0.000682000985115548 -0.00020192400931680343" rpy="0 0 0"/>
    <mass value="0.000475309135914491"/>
    <inertia ixx="0.0" iyy="0.0" izz="0.0" ixy="-0.0" iyz="-0.0" ixz="0.0"/>
  </inertial>
  <visual>
    <origin xyz="-0.065742 0.0 -0.100509" rpy="0 0 0"/>
    <geometry>
      <mesh filename="package://nybble_description/meshes/neck_horn_1.stl" scale="0.001 0.001 0.001"/>
    </geometry>
    <material name="silver"/>
  </visual>
  <collision>
    <origin xyz="-0.065742 0.0 -0.100509" rpy="0 0 0"/>
    <geometry>
      <mesh filename="package://nybble_description/meshes/neck_horn_1.stl" scale="0.001 0.001 0.001"/>
    </geometry>
  </collision>
</link>

<link name="horn_9_1">
  <inertial>
    <origin xyz="-3.85118776558141e-05 -4.752999946625654e-08 0.00465463153848511" rpy="0 0 0"/>
    <mass value="0.0002804129671460145"/>
    <inertia ixx="0.0" iyy="0.0" izz="0.0" ixy="-0.0" iyz="-0.0" ixz="-0.0"/>
  </inertial>
  <visual>
    <origin xyz="0.062695 0.0 -0.099434" rpy="0 0 0"/>
    <geometry>
      <mesh filename="package://nybble_description/meshes/horn_9_1.stl" scale="0.001 0.001 0.001"/>
    </geometry>
    <material name="silver"/>
  </visual>
  <collision>
    <origin xyz="0.062695 0.0 -0.099434" rpy="0 0 0"/>
    <geometry>
      <mesh filename="package://nybble_description/meshes/horn_9_1.stl" scale="0.001 0.001 0.001"/>
    </geometry>
  </collision>
</link>

<link name="screwr_13_1">
  <inertial>
    <origin xyz="-0.0017439846763351169 1.5341235305519752e-06 -0.0015665068111703345" rpy="0 0 0"/>
    <mass value="0.0002152244327717089"/>
    <inertia ixx="0.0" iyy="0.0" izz="0.0" ixy="0.0" iyz="0.0" ixz="-0.0"/>
  </inertial>
  <visual>
    <origin xyz="-0.069605 0.0 -0.078286" rpy="0 0 0"/>
    <geometry>
      <mesh filename="package://nybble_description/meshes/screwr_13_1.stl" scale="0.001 0.001 0.001"/>
    </geometry>
    <material name="silver"/>
  </visual>
  <collision>
    <origin xyz="-0.069605 0.0 -0.078286" rpy="0 0 0"/>
    <geometry>
      <mesh filename="package://nybble_description/meshes/screwr_13_1.stl" scale="0.001 0.001 0.001"/>
    </geometry>
  </collision>
</link>

<link name="servo_lft_1">
  <inertial>
    <origin xyz="0.0033274175172007675 -0.01570537812881572 -0.0033266848952857517" rpy="0 0 0"/>
    <mass value="0.01828047310153439"/>
    <inertia ixx="2e-06" iyy="1e-06" izz="2e-06" ixy="0.0" iyz="-0.0" ixz="0.0"/>
  </inertial>
  <visual>
    <origin xyz="-0.03715 -0.04595 -0.04206" rpy="0 0 0"/>
    <geometry>
      <mesh filename="package://nybble_description/meshes/servo_lft_1.stl" scale="0.001 0.001 0.001"/>
    </geometry>
    <material name="silver"/>
  </visual>
  <collision>
    <origin xyz="-0.03715 -0.04595 -0.04206" rpy="0 0 0"/>
    <geometry>
      <mesh filename="package://nybble_description/meshes/servo_lft_1.stl" scale="0.001 0.001 0.001"/>
    </geometry>
  </collision>
</link>

<joint name="Rigid 1" type="fixed">
  <origin xyz="0.066161 -0.0355 0.075887" rpy="0 0 0"/>
  <parent link="base_link"/>
  <child link="servo_rfs__1"/>
</joint>

<joint name="Rigid 2" type="fixed">
  <origin xyz="0.0 -0.00145 0.0" rpy="0 0 0"/>
  <parent link="horn_1__1"/>
  <child link="thigh_rf_1"/>
</joint>

<joint name="Rigid 3" type="fixed">
  <origin xyz="-0.023 -0.0025 -0.039837" rpy="0 0 0"/>
  <parent link="thigh_rf_1"/>
  <child link="horn_2__1"/>
</joint>

<joint name="Rigid 5" type="fixed">
  <origin xyz="-0.00601 0.0085 0.006011" rpy="0 0 0"/>
  <parent link="servo_rft_1"/>
  <child link="shank_rf_1"/>
</joint>

<joint name="Rigid 7" type="fixed">
  <origin xyz="0.066161 0.0355 0.075887" rpy="0 0 0"/>
  <parent link="base_link"/>
  <child link="servo_lfs__1"/>
</joint>

<joint name="Rigid 8" type="fixed">
  <origin xyz="0.0 0.00145 0.0" rpy="0 0 0"/>
  <parent link="horn_3_1"/>
  <child link="thigh_lf__1"/>
</joint>

<joint name="Rigid 9" type="fixed">
  <origin xyz="-0.023 0.0025 -0.039837" rpy="0 0 0"/>
  <parent link="thigh_lf__1"/>
  <child link="horn_4_1"/>
</joint>

<joint name="Rigid 10" type="fixed">
  <origin xyz="-0.00601 -0.0085 0.006011" rpy="0 0 0"/>
  <parent link="servo_lft_1"/>
  <child link="shank_lf__1"/>
</joint>

<joint name="Rigid 13" type="fixed">
  <origin xyz="-0.066161 0.0355 0.075887" rpy="0 0 0"/>
  <parent link="base_link"/>
  <child link="servo_lrs__1"/>
</joint>

<joint name="Rigid 14" type="fixed">
  <origin xyz="-1e-06 -0.00145 0.0" rpy="0 0 0"/>
  <parent link="horn_5_1"/>
  <child link="thigh_rr_1"/>
</joint>

<joint name="Rigid 15" type="fixed">
  <origin xyz="0.023 -0.0025 -0.039837" rpy="0 0 0"/>
  <parent link="thigh_rr_1"/>
  <child link="horn_6_1"/>
</joint>

<joint name="Rigid 16" type="fixed">
  <origin xyz="0.006011 0.0085 0.006011" rpy="0 0 0"/>
  <parent link="servo_rrt_1"/>
  <child link="shank_rr_1"/>
</joint>

<joint name="Rigid 19" type="fixed">
  <origin xyz="-0.066161 -0.0355 0.075887" rpy="0 0 0"/>
  <parent link="base_link"/>
  <child link="servo_rrs__1"/>
</joint>

<joint name="Rigid 20" type="fixed">
  <origin xyz="-1e-06 0.00145 0.0" rpy="0 0 0"/>
  <parent link="horn_8_1"/>
  <child link="thigh_lr__1"/>
</joint>

<joint name="Rigid 22" type="fixed">
  <origin xyz="0.006011 -0.0085 0.006011" rpy="0 0 0"/>
  <parent link="servo_lrt__1"/>
  <child link="shank_lr_1"/>
</joint>

<joint name="Rigid 25" type="fixed">
  <origin xyz="0.023 0.0025 -0.039837" rpy="0 0 0"/>
  <parent link="thigh_lr__1"/>
  <child link="horn_7__1"/>
</joint>

<joint name="Rigid 26" type="fixed">
  <origin xyz="-0.070403 0.0 0.08013" rpy="0 0 0"/>
  <parent link="base_link"/>
  <child link="servo_tail__1"/>
</joint>

<joint name="Rigid 27" type="fixed">
  <origin xyz="0.06305 0.006 0.092292" rpy="0 0 0"/>
  <parent link="base_link"/>
  <child link="servo_neck__1"/>
</joint>

<joint name="Rigid 28" type="fixed">
  <origin xyz="0.011515 0.0032 -0.000353" rpy="0 0 0"/>
  <parent link="head__1"/>
  <child link="ultrasonic__1"/>
</joint>

<joint name="Rigid 29" type="fixed">
  <origin xyz="0.000999 0.009 0.019073" rpy="0 0 0"/>
  <parent link="servo_head__1"/>
  <child link="head__1"/>
</joint>

<joint name="Rigid 31" type="fixed">
  <origin xyz="0.009508 -0.0161 0.00984" rpy="0 0 0"/>
  <parent link="neck__1"/>
  <child link="horn_10_1"/>
</joint>

<joint name="Rigid 32" type="fixed">
  <origin xyz="0.005261 0.0 -0.004347" rpy="0 0 0"/>
  <parent link="neck_horn_1"/>
  <child link="neck__1"/>
</joint>

<joint name="Rigid 34" type="fixed">
  <origin xyz="0.0 0.0 0.0" rpy="0 0 0"/>
  <parent link="screwr_1_1"/>
  <child link="tail_1"/>
</joint>

<joint name="Rigid 35" type="fixed">
  <origin xyz="0.002687 0.0 0.009475" rpy="0 0 0"/>
  <parent link="horn_9_1"/>
  <child link="screwr_1_1"/>
</joint>

<joint name="Rigid 37" type="fixed">
  <origin xyz="-0.029 -0.0245 0.094478" rpy="0 0 0"/>
  <parent link="base_link"/>
  <child link="pcb__1"/>
</joint>

<joint name="Rigid 38" type="fixed">
  <origin xyz="-0.00924 0.0 0.073412" rpy="0 0 0"/>
  <parent link="base_link"/>
  <child link="battery_1"/>
</joint>

<joint name="Rigid 39" type="fixed">
  <origin xyz="0.0 -0.002 0.0" rpy="0 0 0"/>
  <parent link="servo_rrs__1"/>
  <child link="screwr_4_1"/>
</joint>

<joint name="Rigid 40" type="fixed">
  <origin xyz="0.019516 -0.002 0.019516" rpy="0 0 0"/>
  <parent link="servo_rrs__1"/>
  <child link="screwr_5_1"/>
</joint>

<joint name="Rigid 41" type="fixed">
  <origin xyz="-0.013505 0.00845 -0.013505" rpy="0 0 0"/>
  <parent link="servo_rrt_1"/>
  <child link="screwr_2_1"/>
</joint>

<joint name="Rigid 42" type="fixed">
  <origin xyz="0.006011 0.00845 0.006011" rpy="0 0 0"/>
  <parent link="servo_rrt_1"/>
  <child link="screwr_3_1"/>
</joint>

<joint name="Rigid 43" type="fixed">
  <origin xyz="0.013506 0.00845 -0.013505" rpy="0 0 0"/>
  <parent link="servo_rft_1"/>
  <child link="screwr_6_1"/>
</joint>

<joint name="Rigid 44" type="fixed">
  <origin xyz="-0.00601 0.00845 0.006011" rpy="0 0 0"/>
  <parent link="servo_rft_1"/>
  <child link="screwr_7_1"/>
</joint>

<joint name="Rigid 45" type="fixed">
  <origin xyz="0.0 -0.002 0.0" rpy="0 0 0"/>
  <parent link="servo_rfs__1"/>
  <child link="screw_9_1"/>
</joint>

<joint name="Rigid 46" type="fixed">
  <origin xyz="-0.019516 -0.002 0.019516" rpy="0 0 0"/>
  <parent link="servo_rfs__1"/>
  <child link="screw_8_1"/>
</joint>

<joint name="Rigid 47" type="fixed">
  <origin xyz="0.0 0.002 0.0" rpy="0 0 0"/>
  <parent link="servo_lfs__1"/>
  <child link="screwr_14_1"/>
</joint>

<joint name="Rigid 48" type="fixed">
  <origin xyz="-0.019516 0.002 0.019516" rpy="0 0 0"/>
  <parent link="servo_lfs__1"/>
  <child link="screwr_20_1"/>
</joint>

<joint name="Rigid 49" type="fixed">
  <origin xyz="-0.00601 -0.00845 0.006011" rpy="0 0 0"/>
  <parent link="servo_lft_1"/>
  <child link="screwr_16_1"/>
</joint>

<joint name="Rigid 50" type="fixed">
  <origin xyz="0.013506 -0.00845 -0.013505" rpy="0 0 0"/>
  <parent link="servo_lft_1"/>
  <child link="screwr_15_1"/>
</joint>

<joint name="Rigid 51" type="fixed">
  <origin xyz="0.019516 0.002 0.019516" rpy="0 0 0"/>
  <parent link="servo_lrs__1"/>
  <child link="screwr_18_1"/>
</joint>

<joint name="Rigid 52" type="fixed">
  <origin xyz="0.0 0.002 0.0" rpy="0 0 0"/>
  <parent link="servo_lrs__1"/>
  <child link="screwr_19_1"/>
</joint>

<joint name="Rigid 53" type="fixed">
  <origin xyz="-0.013505 -0.00845 -0.013505" rpy="0 0 0"/>
  <parent link="servo_lrt__1"/>
  <child link="screwr_21_1"/>
</joint>

<joint name="Rigid 54" type="fixed">
  <origin xyz="0.006011 -0.00845 0.006011" rpy="0 0 0"/>
  <parent link="servo_lrt__1"/>
  <child link="screwr_17_1"/>
</joint>

<joint name="Rigid 55" type="fixed">
  <origin xyz="0.001 0.0085 0.019073" rpy="0 0 0"/>
  <parent link="servo_head__1"/>
  <child link="screwr_11_1"/>
</joint>

<joint name="Rigid 56" type="fixed">
  <origin xyz="-0.000445 0.0085 -0.008489" rpy="0 0 0"/>
  <parent link="servo_head__1"/>
  <child link="screwr_10_1"/>
</joint>

<joint name="Rigid 57" type="fixed">
  <origin xyz="0.016501 0.00345 -0.028578" rpy="0 0 0"/>
  <parent link="thigh_rr_1"/>
  <child link="screwb_4_1"/>
</joint>

<joint name="Rigid 58" type="fixed">
  <origin xyz="0.019713 0.00345 -0.04763" rpy="0 0 0"/>
  <parent link="thigh_rr_1"/>
  <child link="screwb_5_1"/>
</joint>

<joint name="Rigid 59" type="fixed">
  <origin xyz="0.031393 0.00345 -0.040886" rpy="0 0 0"/>
  <parent link="thigh_rr_1"/>
  <child link="screwb_6_1"/>
</joint>

<joint name="Rigid 60" type="fixed">
  <origin xyz="0.006501 0.00345 -0.011258" rpy="0 0 0"/>
  <parent link="thigh_rr_1"/>
  <child link="screwb_3_1"/>
</joint>

<joint name="Rigid 61" type="fixed">
  <origin xyz="0.003288 0.00345 0.007793" rpy="0 0 0"/>
  <parent link="thigh_rr_1"/>
  <child link="screwb_2_1"/>
</joint>

<joint name="Rigid 62" type="fixed">
  <origin xyz="-0.008392 0.00345 0.00105" rpy="0 0 0"/>
  <parent link="thigh_rr_1"/>
  <child link="screwb_1_1"/>
</joint>

<joint name="Rigid 63" type="fixed">
  <origin xyz="-0.0165 0.00345 -0.028578" rpy="0 0 0"/>
  <parent link="thigh_rf_1"/>
  <child link="screwb_10_1"/>
</joint>

<joint name="Rigid 64" type="fixed">
  <origin xyz="-0.003287 0.00345 0.007793" rpy="0 0 0"/>
  <parent link="thigh_rf_1"/>
  <child link="screwb_7_1"/>
</joint>

<joint name="Rigid 65" type="fixed">
  <origin xyz="-0.019712 0.00345 -0.04763" rpy="0 0 0"/>
  <parent link="thigh_rf_1"/>
  <child link="screwb_12_1"/>
</joint>

<joint name="Rigid 66" type="fixed">
  <origin xyz="-0.031392 0.00345 -0.040886" rpy="0 0 0"/>
  <parent link="thigh_rf_1"/>
  <child link="screwb_11_1"/>
</joint>

<joint name="Rigid 67" type="fixed">
  <origin xyz="0.008393 0.00345 0.00105" rpy="0 0 0"/>
  <parent link="thigh_rf_1"/>
  <child link="screwb_8_1"/>
</joint>

<joint name="Rigid 68" type="fixed">
  <origin xyz="-0.0065 0.00345 -0.011258" rpy="0 0 0"/>
  <parent link="thigh_rf_1"/>
  <child link="screwb_9_1"/>
</joint>

<joint name="Rigid 69" type="fixed">
  <origin xyz="-0.00924 0.0 0.084812" rpy="0 0 0"/>
  <parent link="base_link"/>
  <child link="screw_bat_1"/>
</joint>

<joint name="Rigid 70" type="fixed">
  <origin xyz="0.01386 0.0 0.084812" rpy="0 0 0"/>
  <parent link="base_link"/>
  <child link="screw_batt_1"/>
</joint>

<joint name="Rigid 71" type="fixed">
  <origin xyz="-0.019712 -0.00345 -0.04763" rpy="0 0 0"/>
  <parent link="thigh_lf__1"/>
  <child link="screwb_18_1"/>
</joint>

<joint name="Rigid 72" type="fixed">
  <origin xyz="-0.0065 -0.00345 -0.011258" rpy="0 0 0"/>
  <parent link="thigh_lf__1"/>
  <child link="screwb_15_1"/>
</joint>

<joint name="Rigid 73" type="fixed">
  <origin xyz="-0.003287 -0.00345 0.007793" rpy="0 0 0"/>
  <parent link="thigh_lf__1"/>
  <child link="screwb_14_1"/>
</joint>

<joint name="Rigid 74" type="fixed">
  <origin xyz="-0.0165 -0.00345 -0.028578" rpy="0 0 0"/>
  <parent link="thigh_lf__1"/>
  <child link="screwb_16_1"/>
</joint>

<joint name="Rigid 75" type="fixed">
  <origin xyz="0.008393 -0.00345 0.00105" rpy="0 0 0"/>
  <parent link="thigh_lf__1"/>
  <child link="screwb_13_1"/>
</joint>

<joint name="Rigid 76" type="fixed">
  <origin xyz="-0.031392 -0.00345 -0.040886" rpy="0 0 0"/>
  <parent link="thigh_lf__1"/>
  <child link="screwb_17_1"/>
</joint>

<joint name="Rigid 77" type="fixed">
  <origin xyz="0.016501 -0.00345 -0.028578" rpy="0 0 0"/>
  <parent link="thigh_lr__1"/>
  <child link="screwb_22_1"/>
</joint>

<joint name="Rigid 78" type="fixed">
  <origin xyz="0.006501 -0.00345 -0.011258" rpy="0 0 0"/>
  <parent link="thigh_lr__1"/>
  <child link="screwb_23_1"/>
</joint>

<joint name="Rigid 79" type="fixed">
  <origin xyz="-0.008392 -0.00345 0.00105" rpy="0 0 0"/>
  <parent link="thigh_lr__1"/>
  <child link="screwb_24_1"/>
</joint>

<joint name="Rigid 80" type="fixed">
  <origin xyz="0.003288 -0.00345 0.007793" rpy="0 0 0"/>
  <parent link="thigh_lr__1"/>
  <child link="screwb_19_1"/>
</joint>

<joint name="Rigid 81" type="fixed">
  <origin xyz="0.019713 -0.00345 -0.04763" rpy="0 0 0"/>
  <parent link="thigh_lr__1"/>
  <child link="screwb_20_1"/>
</joint>

<joint name="Rigid 82" type="fixed">
  <origin xyz="0.031393 -0.00345 -0.040886" rpy="0 0 0"/>
  <parent link="thigh_lr__1"/>
  <child link="screwb_21_1"/>
</joint>

<joint name="Rigid 84" type="fixed">
  <origin xyz="0.0 0.0019 0.0" rpy="0 0 0"/>
  <parent link="horn_10_1"/>
  <child link="screw_head_2"/>
</joint>

<joint name="Rigid 85" type="fixed">
  <origin xyz="0.000466 0.0019 0.00957" rpy="0 0 0"/>
  <parent link="horn_10_1"/>
  <child link="screw_headd__1"/>
</joint>

<joint name="Rigid 86" type="fixed">
  <origin xyz="-0.00199 -0.0068 0.007292" rpy="0 0 0"/>
  <parent link="neck__1"/>
  <child link="screw_neckk_1"/>
</joint>

<joint name="Rigid 87" type="fixed">
  <origin xyz="-0.00199 0.0068 0.007292" rpy="0 0 0"/>
  <parent link="neck__1"/>
  <child link="screw_neck_1"/>
</joint>

<joint name="Rigid 88" type="fixed">
  <origin xyz="-0.063003 0.0 -0.07163" rpy="0 0 0"/>
  <parent link="tail_1"/>
  <child link="screwr_12_1"/>
</joint>

<joint name="shrfs_joint" type="continuous">
  <origin xyz="-0.006011 -0.014 0.00601" rpy="0 0 0"/>
  <parent link="servo_rfs__1"/>
  <child link="horn_1__1"/>
  <axis xyz="0.0 -1.0 -0.0"/>
</joint>

<joint name="shrft_joint" type="continuous">
  <origin xyz="0.0 0.0075 0.0" rpy="0 0 0"/>
  <parent link="horn_2__1"/>
  <child link="servo_rft_1"/>
  <axis xyz="-0.0 -1.0 -0.0"/>
</joint>

<joint name="shrrs_joint" type="continuous">
  <origin xyz="0.006011 -0.014 0.00601" rpy="0 0 0"/>
  <parent link="servo_rrs__1"/>
  <child link="horn_5_1"/>
  <axis xyz="0.0 1.0 0.0"/>
</joint>

<joint name="shrrt_joint" type="continuous">
  <origin xyz="0.0 0.0075 0.0" rpy="0 0 0"/>
  <parent link="horn_6_1"/>
  <child link="servo_rrt_1"/>
  <axis xyz="-0.0 -1.0 -0.0"/>
</joint>

<joint name="shlfs_joint" type="continuous">
  <origin xyz="-0.006011 0.014 0.00601" rpy="0 0 0"/>
  <parent link="servo_lfs__1"/>
  <child link="horn_3_1"/>
  <axis xyz="-0.0 -1.0 0.0"/>
</joint>

<joint name="shlrs_joint" type="continuous">
  <origin xyz="0.006011 0.014 0.00601" rpy="0 0 0"/>
  <parent link="servo_lrs__1"/>
  <child link="horn_8_1"/>
  <axis xyz="-0.0 1.0 -0.0"/>
</joint>

<joint name="shlrt_joint" type="continuous">
  <origin xyz="0.0 -0.0075 0.0" rpy="0 0 0"/>
  <parent link="horn_7__1"/>
  <child link="servo_lrt__1"/>
  <axis xyz="0.0 -1.0 0.0"/>
</joint>

<joint name="head_joint" type="continuous">
  <origin xyz="0.005016 0.0045 0.004517" rpy="0 0 0"/>
  <parent link="horn_10_1"/>
  <child link="servo_head__1"/>
  <axis xyz="-0.0 -1.0 -0.0"/>
</joint>

<joint name="neck_joint" type="continuous">
  <origin xyz="0.002692 -0.006 0.008217" rpy="0 0 0"/>
  <parent link="servo_neck__1"/>
  <child link="neck_horn_1"/>
  <axis xyz="-0.743145 0.0 -0.669131"/>
</joint>

<joint name="tail_joint" type="continuous">
  <origin xyz="0.007708 0.0 0.019304" rpy="0 0 0"/>
  <parent link="servo_tail__1"/>
  <child link="horn_9_1"/>
  <axis xyz="0.707107 0.0 -0.707107"/>
</joint>

<joint name="Rigid 100" type="fixed">
  <origin xyz="0.006555 -0.006 -0.014006" rpy="0 0 0"/>
  <parent link="servo_neck__1"/>
  <child link="screwr_13_1"/>
</joint>

<joint name="shlft_joint" type="continuous">
  <origin xyz="0.0 -0.0075 0.0" rpy="0 0 0"/>
  <parent link="horn_4_1"/>
  <child link="servo_lft_1"/>
  <axis xyz="0.0 -1.0 0.0"/>
</joint>

</robot>
